2023-05-04T16:29:08.840361666Z I0504 16:29:08.840282       1 flags.go:64] FLAG: --add-dir-header="false"
2023-05-04T16:29:08.840361666Z I0504 16:29:08.840337       1 flags.go:64] FLAG: --allow-metric-labels="[]"
2023-05-04T16:29:08.840361666Z I0504 16:29:08.840343       1 flags.go:64] FLAG: --alsologtostderr="false"
2023-05-04T16:29:08.840361666Z I0504 16:29:08.840345       1 flags.go:64] FLAG: --authentication-kubeconfig="/etc/kubernetes/static-pod-resources/configmaps/scheduler-kubeconfig/kubeconfig"
2023-05-04T16:29:08.840361666Z I0504 16:29:08.840350       1 flags.go:64] FLAG: --authentication-skip-lookup="false"
2023-05-04T16:29:08.840420957Z I0504 16:29:08.840354       1 flags.go:64] FLAG: --authentication-token-webhook-cache-ttl="10s"
2023-05-04T16:29:08.840420957Z I0504 16:29:08.840358       1 flags.go:64] FLAG: --authentication-tolerate-lookup-failure="true"
2023-05-04T16:29:08.840420957Z I0504 16:29:08.840360       1 flags.go:64] FLAG: --authorization-always-allow-paths="[/healthz,/readyz,/livez]"
2023-05-04T16:29:08.840420957Z I0504 16:29:08.840366       1 flags.go:64] FLAG: --authorization-kubeconfig="/etc/kubernetes/static-pod-resources/configmaps/scheduler-kubeconfig/kubeconfig"
2023-05-04T16:29:08.840420957Z I0504 16:29:08.840369       1 flags.go:64] FLAG: --authorization-webhook-cache-authorized-ttl="10s"
2023-05-04T16:29:08.840420957Z I0504 16:29:08.840372       1 flags.go:64] FLAG: --authorization-webhook-cache-unauthorized-ttl="10s"
2023-05-04T16:29:08.840420957Z I0504 16:29:08.840374       1 flags.go:64] FLAG: --bind-address="0.0.0.0"
2023-05-04T16:29:08.840420957Z I0504 16:29:08.840378       1 flags.go:64] FLAG: --cert-dir="/var/run/kubernetes"
2023-05-04T16:29:08.840420957Z I0504 16:29:08.840380       1 flags.go:64] FLAG: --client-ca-file=""
2023-05-04T16:29:08.840420957Z I0504 16:29:08.840382       1 flags.go:64] FLAG: --config="/etc/kubernetes/static-pod-resources/configmaps/config/config.yaml"
2023-05-04T16:29:08.840420957Z I0504 16:29:08.840385       1 flags.go:64] FLAG: --contention-profiling="true"
2023-05-04T16:29:08.840420957Z I0504 16:29:08.840388       1 flags.go:64] FLAG: --disabled-metrics="[]"
2023-05-04T16:29:08.840420957Z I0504 16:29:08.840391       1 flags.go:64] FLAG: --feature-gates="APIPriorityAndFairness=true,CSIMigrationAzureFile=false,CSIMigrationvSphere=false,DownwardAPIHugePages=true,RotateKubeletServerCertificate=true"
2023-05-04T16:29:08.840420957Z I0504 16:29:08.840405       1 flags.go:64] FLAG: --help="false"
2023-05-04T16:29:08.840420957Z I0504 16:29:08.840408       1 flags.go:64] FLAG: --http2-max-streams-per-connection="0"
2023-05-04T16:29:08.840420957Z I0504 16:29:08.840411       1 flags.go:64] FLAG: --kube-api-burst="100"
2023-05-04T16:29:08.840420957Z I0504 16:29:08.840414       1 flags.go:64] FLAG: --kube-api-content-type="application/vnd.kubernetes.protobuf"
2023-05-04T16:29:08.840420957Z I0504 16:29:08.840417       1 flags.go:64] FLAG: --kube-api-qps="50"
2023-05-04T16:29:08.840433311Z I0504 16:29:08.840420       1 flags.go:64] FLAG: --kubeconfig=""
2023-05-04T16:29:08.840433311Z I0504 16:29:08.840423       1 flags.go:64] FLAG: --leader-elect="true"
2023-05-04T16:29:08.840433311Z I0504 16:29:08.840425       1 flags.go:64] FLAG: --leader-elect-lease-duration="15s"
2023-05-04T16:29:08.840433311Z I0504 16:29:08.840427       1 flags.go:64] FLAG: --leader-elect-renew-deadline="10s"
2023-05-04T16:29:08.840433311Z I0504 16:29:08.840430       1 flags.go:64] FLAG: --leader-elect-resource-lock="leases"
2023-05-04T16:29:08.840440043Z I0504 16:29:08.840432       1 flags.go:64] FLAG: --leader-elect-resource-name="kube-scheduler"
2023-05-04T16:29:08.840440043Z I0504 16:29:08.840434       1 flags.go:64] FLAG: --leader-elect-resource-namespace="kube-system"
2023-05-04T16:29:08.840440043Z I0504 16:29:08.840437       1 flags.go:64] FLAG: --leader-elect-retry-period="2s"
2023-05-04T16:29:08.840449301Z I0504 16:29:08.840439       1 flags.go:64] FLAG: --lock-object-name="kube-scheduler"
2023-05-04T16:29:08.840449301Z I0504 16:29:08.840442       1 flags.go:64] FLAG: --lock-object-namespace="kube-system"
2023-05-04T16:29:08.840449301Z I0504 16:29:08.840444       1 flags.go:64] FLAG: --log-backtrace-at=":0"
2023-05-04T16:29:08.840449301Z I0504 16:29:08.840447       1 flags.go:64] FLAG: --log-dir=""
2023-05-04T16:29:08.840455582Z I0504 16:29:08.840449       1 flags.go:64] FLAG: --log-file=""
2023-05-04T16:29:08.840455582Z I0504 16:29:08.840451       1 flags.go:64] FLAG: --log-file-max-size="1800"
2023-05-04T16:29:08.840460812Z I0504 16:29:08.840454       1 flags.go:64] FLAG: --log-flush-frequency="5s"
2023-05-04T16:29:08.840460812Z I0504 16:29:08.840456       1 flags.go:64] FLAG: --log-json-info-buffer-size="0"
2023-05-04T16:29:08.840466082Z I0504 16:29:08.840461       1 flags.go:64] FLAG: --log-json-split-stream="false"
2023-05-04T16:29:08.840466082Z I0504 16:29:08.840463       1 flags.go:64] FLAG: --logging-format="text"
2023-05-04T16:29:08.840471212Z I0504 16:29:08.840465       1 flags.go:64] FLAG: --logtostderr="true"
2023-05-04T16:29:08.840471212Z I0504 16:29:08.840468       1 flags.go:64] FLAG: --master=""
2023-05-04T16:29:08.840476301Z I0504 16:29:08.840470       1 flags.go:64] FLAG: --one-output="false"
2023-05-04T16:29:08.840476301Z I0504 16:29:08.840472       1 flags.go:64] FLAG: --permit-address-sharing="false"
2023-05-04T16:29:08.840476301Z I0504 16:29:08.840474       1 flags.go:64] FLAG: --permit-port-sharing="false"
2023-05-04T16:29:08.840481842Z I0504 16:29:08.840477       1 flags.go:64] FLAG: --pod-max-in-unschedulable-pods-duration="5m0s"
2023-05-04T16:29:08.840481842Z I0504 16:29:08.840479       1 flags.go:64] FLAG: --profiling="true"
2023-05-04T16:29:08.840487011Z I0504 16:29:08.840481       1 flags.go:64] FLAG: --requestheader-allowed-names="[]"
2023-05-04T16:29:08.840487011Z I0504 16:29:08.840485       1 flags.go:64] FLAG: --requestheader-client-ca-file=""
2023-05-04T16:29:08.840493253Z I0504 16:29:08.840489       1 flags.go:64] FLAG: --requestheader-extra-headers-prefix="[x-remote-extra-]"
2023-05-04T16:29:08.840497872Z I0504 16:29:08.840492       1 flags.go:64] FLAG: --requestheader-group-headers="[x-remote-group]"
2023-05-04T16:29:08.840502591Z I0504 16:29:08.840496       1 flags.go:64] FLAG: --requestheader-username-headers="[x-remote-user]"
2023-05-04T16:29:08.840502591Z I0504 16:29:08.840499       1 flags.go:64] FLAG: --secure-port="10259"
2023-05-04T16:29:08.840507560Z I0504 16:29:08.840501       1 flags.go:64] FLAG: --show-hidden-metrics-for-version=""
2023-05-04T16:29:08.840507560Z I0504 16:29:08.840504       1 flags.go:64] FLAG: --skip-headers="false"
2023-05-04T16:29:08.840512479Z I0504 16:29:08.840506       1 flags.go:64] FLAG: --skip-log-headers="false"
2023-05-04T16:29:08.840512479Z I0504 16:29:08.840508       1 flags.go:64] FLAG: --stderrthreshold="2"
2023-05-04T16:29:08.840517398Z I0504 16:29:08.840511       1 flags.go:64] FLAG: --tls-cert-file="/etc/kubernetes/static-pod-resources/secrets/serving-cert/tls.crt"
2023-05-04T16:29:08.840522057Z I0504 16:29:08.840514       1 flags.go:64] FLAG: --tls-cipher-suites="[TLS_ECDHE_ECDSA_WITH_AES_128_GCM_SHA256,TLS_ECDHE_RSA_WITH_AES_128_GCM_SHA256,TLS_ECDHE_ECDSA_WITH_AES_256_GCM_SHA384,TLS_ECDHE_RSA_WITH_AES_256_GCM_SHA384,TLS_ECDHE_ECDSA_WITH_CHACHA20_POLY1305_SHA256,TLS_ECDHE_RSA_WITH_CHACHA20_POLY1305_SHA256]"
2023-05-04T16:29:08.840529321Z I0504 16:29:08.840520       1 flags.go:64] FLAG: --tls-min-version="VersionTLS12"
2023-05-04T16:29:08.840529321Z I0504 16:29:08.840523       1 flags.go:64] FLAG: --tls-private-key-file="/etc/kubernetes/static-pod-resources/secrets/serving-cert/tls.key"
2023-05-04T16:29:08.840534390Z I0504 16:29:08.840528       1 flags.go:64] FLAG: --tls-sni-cert-key="[]"
2023-05-04T16:29:08.840534390Z I0504 16:29:08.840531       1 flags.go:64] FLAG: --unsupported-kube-api-over-localhost="false"
2023-05-04T16:29:08.840539300Z I0504 16:29:08.840534       1 flags.go:64] FLAG: --v="2"
2023-05-04T16:29:08.840543908Z I0504 16:29:08.840537       1 flags.go:64] FLAG: --version="false"
2023-05-04T16:29:08.840548557Z I0504 16:29:08.840541       1 flags.go:64] FLAG: --vmodule=""
2023-05-04T16:29:08.840548557Z I0504 16:29:08.840546       1 flags.go:64] FLAG: --write-config-to=""
2023-05-04T16:29:08.865886285Z I0504 16:29:08.865844       1 dynamic_serving_content.go:113] "Loaded a new cert/key pair" name="serving-cert::/etc/kubernetes/static-pod-resources/secrets/serving-cert/tls.crt::/etc/kubernetes/static-pod-resources/secrets/serving-cert/tls.key"
2023-05-04T16:29:19.221097144Z W0504 16:29:19.221051       1 authentication.go:346] Error looking up in-cluster authentication configuration: Get "https://api-int.sno.gw.lo:6443/api/v1/namespaces/kube-system/configmaps/extension-apiserver-authentication": net/http: TLS handshake timeout
2023-05-04T16:29:19.221097144Z W0504 16:29:19.221075       1 authentication.go:347] Continuing without authentication configuration. This may treat all requests as anonymous.
2023-05-04T16:29:19.221097144Z W0504 16:29:19.221081       1 authentication.go:348] To require authentication configuration lookup to succeed, set --authentication-tolerate-lookup-failure=false
2023-05-04T16:29:22.343927546Z I0504 16:29:22.343540       1 configfile.go:102] "Using component config" config=<
2023-05-04T16:29:22.343927546Z 	apiVersion: kubescheduler.config.k8s.io/v1beta3
2023-05-04T16:29:22.343927546Z 	clientConnection:
2023-05-04T16:29:22.343927546Z 	  acceptContentTypes: ""
2023-05-04T16:29:22.343927546Z 	  burst: 100
2023-05-04T16:29:22.343927546Z 	  contentType: application/vnd.kubernetes.protobuf
2023-05-04T16:29:22.343927546Z 	  kubeconfig: /etc/kubernetes/static-pod-resources/configmaps/scheduler-kubeconfig/kubeconfig
2023-05-04T16:29:22.343927546Z 	  qps: 50
2023-05-04T16:29:22.343927546Z 	enableContentionProfiling: true
2023-05-04T16:29:22.343927546Z 	enableProfiling: true
2023-05-04T16:29:22.343927546Z 	kind: KubeSchedulerConfiguration
2023-05-04T16:29:22.343927546Z 	leaderElection:
2023-05-04T16:29:22.343927546Z 	  leaderElect: true
2023-05-04T16:29:22.343927546Z 	  leaseDuration: 2m17s
2023-05-04T16:29:22.343927546Z 	  renewDeadline: 1m47s
2023-05-04T16:29:22.343927546Z 	  resourceLock: configmapsleases
2023-05-04T16:29:22.343927546Z 	  resourceName: kube-scheduler
2023-05-04T16:29:22.343927546Z 	  resourceNamespace: openshift-kube-scheduler
2023-05-04T16:29:22.343927546Z 	  retryPeriod: 26s
2023-05-04T16:29:22.343927546Z 	parallelism: 16
2023-05-04T16:29:22.343927546Z 	percentageOfNodesToScore: 0
2023-05-04T16:29:22.343927546Z 	podInitialBackoffSeconds: 1
2023-05-04T16:29:22.343927546Z 	podMaxBackoffSeconds: 10
2023-05-04T16:29:22.343927546Z 	profiles:
2023-05-04T16:29:22.343927546Z 	- pluginConfig:
2023-05-04T16:29:22.343927546Z 	  - args:
2023-05-04T16:29:22.343927546Z 	      apiVersion: kubescheduler.config.k8s.io/v1beta3
2023-05-04T16:29:22.343927546Z 	      kind: DefaultPreemptionArgs
2023-05-04T16:29:22.343927546Z 	      minCandidateNodesAbsolute: 100
2023-05-04T16:29:22.343927546Z 	      minCandidateNodesPercentage: 10
2023-05-04T16:29:22.343927546Z 	    name: DefaultPreemption
2023-05-04T16:29:22.343927546Z 	  - args:
2023-05-04T16:29:22.343927546Z 	      apiVersion: kubescheduler.config.k8s.io/v1beta3
2023-05-04T16:29:22.343927546Z 	      hardPodAffinityWeight: 1
2023-05-04T16:29:22.343927546Z 	      kind: InterPodAffinityArgs
2023-05-04T16:29:22.343927546Z 	    name: InterPodAffinity
2023-05-04T16:29:22.343927546Z 	  - args:
2023-05-04T16:29:22.343927546Z 	      apiVersion: kubescheduler.config.k8s.io/v1beta3
2023-05-04T16:29:22.343927546Z 	      kind: NodeAffinityArgs
2023-05-04T16:29:22.343927546Z 	    name: NodeAffinity
2023-05-04T16:29:22.343927546Z 	  - args:
2023-05-04T16:29:22.343927546Z 	      apiVersion: kubescheduler.config.k8s.io/v1beta3
2023-05-04T16:29:22.343927546Z 	      kind: NodeResourcesBalancedAllocationArgs
2023-05-04T16:29:22.343927546Z 	      resources:
2023-05-04T16:29:22.343927546Z 	      - name: cpu
2023-05-04T16:29:22.343927546Z 	        weight: 1
2023-05-04T16:29:22.343927546Z 	      - name: memory
2023-05-04T16:29:22.343927546Z 	        weight: 1
2023-05-04T16:29:22.343927546Z 	    name: NodeResourcesBalancedAllocation
2023-05-04T16:29:22.343927546Z 	  - args:
2023-05-04T16:29:22.343927546Z 	      apiVersion: kubescheduler.config.k8s.io/v1beta3
2023-05-04T16:29:22.343927546Z 	      kind: NodeResourcesFitArgs
2023-05-04T16:29:22.343927546Z 	      scoringStrategy:
2023-05-04T16:29:22.343927546Z 	        resources:
2023-05-04T16:29:22.343927546Z 	        - name: cpu
2023-05-04T16:29:22.343927546Z 	          weight: 1
2023-05-04T16:29:22.343927546Z 	        - name: memory
2023-05-04T16:29:22.343927546Z 	          weight: 1
2023-05-04T16:29:22.343927546Z 	        type: LeastAllocated
2023-05-04T16:29:22.343927546Z 	    name: NodeResourcesFit
2023-05-04T16:29:22.343927546Z 	  - args:
2023-05-04T16:29:22.343927546Z 	      apiVersion: kubescheduler.config.k8s.io/v1beta3
2023-05-04T16:29:22.343927546Z 	      defaultingType: System
2023-05-04T16:29:22.343927546Z 	      kind: PodTopologySpreadArgs
2023-05-04T16:29:22.343927546Z 	    name: PodTopologySpread
2023-05-04T16:29:22.343927546Z 	  - args:
2023-05-04T16:29:22.343927546Z 	      apiVersion: kubescheduler.config.k8s.io/v1beta3
2023-05-04T16:29:22.343927546Z 	      bindTimeoutSeconds: 600
2023-05-04T16:29:22.343927546Z 	      kind: VolumeBindingArgs
2023-05-04T16:29:22.343927546Z 	    name: VolumeBinding
2023-05-04T16:29:22.343927546Z 	  plugins:
2023-05-04T16:29:22.343927546Z 	    bind: {}
2023-05-04T16:29:22.343927546Z 	    filter: {}
2023-05-04T16:29:22.343927546Z 	    multiPoint:
2023-05-04T16:29:22.343927546Z 	      enabled:
2023-05-04T16:29:22.343927546Z 	      - name: PrioritySort
2023-05-04T16:29:22.343927546Z 	        weight: 0
2023-05-04T16:29:22.343927546Z 	      - name: NodeUnschedulable
2023-05-04T16:29:22.343927546Z 	        weight: 0
2023-05-04T16:29:22.343927546Z 	      - name: NodeName
2023-05-04T16:29:22.343927546Z 	        weight: 0
2023-05-04T16:29:22.343927546Z 	      - name: TaintToleration
2023-05-04T16:29:22.343927546Z 	        weight: 3
2023-05-04T16:29:22.343927546Z 	      - name: NodeAffinity
2023-05-04T16:29:22.343927546Z 	        weight: 2
2023-05-04T16:29:22.343927546Z 	      - name: NodePorts
2023-05-04T16:29:22.343927546Z 	        weight: 0
2023-05-04T16:29:22.343927546Z 	      - name: NodeResourcesFit
2023-05-04T16:29:22.343927546Z 	        weight: 1
2023-05-04T16:29:22.343927546Z 	      - name: VolumeRestrictions
2023-05-04T16:29:22.343927546Z 	        weight: 0
2023-05-04T16:29:22.343927546Z 	      - name: EBSLimits
2023-05-04T16:29:22.343927546Z 	        weight: 0
2023-05-04T16:29:22.343927546Z 	      - name: GCEPDLimits
2023-05-04T16:29:22.343927546Z 	        weight: 0
2023-05-04T16:29:22.343927546Z 	      - name: NodeVolumeLimits
2023-05-04T16:29:22.343927546Z 	        weight: 0
2023-05-04T16:29:22.343927546Z 	      - name: AzureDiskLimits
2023-05-04T16:29:22.343927546Z 	        weight: 0
2023-05-04T16:29:22.343927546Z 	      - name: VolumeBinding
2023-05-04T16:29:22.343927546Z 	        weight: 0
2023-05-04T16:29:22.343927546Z 	      - name: VolumeZone
2023-05-04T16:29:22.343927546Z 	        weight: 0
2023-05-04T16:29:22.343927546Z 	      - name: PodTopologySpread
2023-05-04T16:29:22.343927546Z 	        weight: 2
2023-05-04T16:29:22.343927546Z 	      - name: InterPodAffinity
2023-05-04T16:29:22.343927546Z 	        weight: 2
2023-05-04T16:29:22.343927546Z 	      - name: DefaultPreemption
2023-05-04T16:29:22.343927546Z 	        weight: 0
2023-05-04T16:29:22.343927546Z 	      - name: NodeResourcesBalancedAllocation
2023-05-04T16:29:22.343927546Z 	        weight: 1
2023-05-04T16:29:22.343927546Z 	      - name: ImageLocality
2023-05-04T16:29:22.343927546Z 	        weight: 1
2023-05-04T16:29:22.343927546Z 	      - name: DefaultBinder
2023-05-04T16:29:22.343927546Z 	        weight: 0
2023-05-04T16:29:22.343927546Z 	    permit: {}
2023-05-04T16:29:22.343927546Z 	    postBind: {}
2023-05-04T16:29:22.343927546Z 	    postFilter: {}
2023-05-04T16:29:22.343927546Z 	    preBind: {}
2023-05-04T16:29:22.343927546Z 	    preFilter: {}
2023-05-04T16:29:22.343927546Z 	    preScore: {}
2023-05-04T16:29:22.343927546Z 	    queueSort: {}
2023-05-04T16:29:22.343927546Z 	    reserve: {}
2023-05-04T16:29:22.343927546Z 	    score: {}
2023-05-04T16:29:22.343927546Z 	  schedulerName: default-scheduler
2023-05-04T16:29:22.343927546Z  >
2023-05-04T16:29:22.343927546Z I0504 16:29:22.343579       1 server.go:152] "Starting Kubernetes Scheduler" version="v1.25.4+a34b9e9"
2023-05-04T16:29:22.343927546Z I0504 16:29:22.343587       1 server.go:154] "Golang settings" GOGC="" GOMAXPROCS="" GOTRACEBACK=""
2023-05-04T16:29:22.355983239Z I0504 16:29:22.353220       1 configmap_cafile_content.go:202] "Starting controller" name="client-ca::kube-system::extension-apiserver-authentication::client-ca-file"
2023-05-04T16:29:22.355983239Z I0504 16:29:22.353240       1 shared_informer.go:255] Waiting for caches to sync for client-ca::kube-system::extension-apiserver-authentication::client-ca-file
2023-05-04T16:29:22.376216294Z I0504 16:29:22.376181       1 tlsconfig.go:200] "Loaded serving cert" certName="serving-cert::/etc/kubernetes/static-pod-resources/secrets/serving-cert/tls.crt::/etc/kubernetes/static-pod-resources/secrets/serving-cert/tls.key" certDetail="\"scheduler.openshift-kube-scheduler.svc\" [serving] validServingFor=[scheduler.openshift-kube-scheduler.svc,scheduler.openshift-kube-scheduler.svc.cluster.local] issuer=\"openshift-service-serving-signer@1683030520\" (2023-05-02 12:30:02 +0000 UTC to 2025-05-01 12:30:03 +0000 UTC (now=2023-05-04 16:29:22.376149489 +0000 UTC))"
2023-05-04T16:29:22.376368069Z I0504 16:29:22.376357       1 named_certificates.go:53] "Loaded SNI cert" index=0 certName="self-signed loopback" certDetail="\"apiserver-loopback-client@1683217749\" [serving] validServingFor=[apiserver-loopback-client] issuer=\"apiserver-loopback-client-ca@1683217749\" (2023-05-04 15:29:08 +0000 UTC to 2024-05-03 15:29:08 +0000 UTC (now=2023-05-04 16:29:22.376335838 +0000 UTC))"
2023-05-04T16:29:22.376399268Z I0504 16:29:22.376392       1 secure_serving.go:210] Serving securely on [::]:10259
2023-05-04T16:29:22.376478166Z I0504 16:29:22.376469       1 dynamic_serving_content.go:132] "Starting controller" name="serving-cert::/etc/kubernetes/static-pod-resources/secrets/serving-cert/tls.crt::/etc/kubernetes/static-pod-resources/secrets/serving-cert/tls.key"
2023-05-04T16:29:22.383396925Z I0504 16:29:22.383361       1 tlsconfig.go:240] "Starting DynamicServingCertificateController"
2023-05-04T16:29:22.487344413Z I0504 16:29:22.486103       1 node_tree.go:65] "Added node in listed group to NodeTree" node="node" zone=""
2023-05-04T16:29:22.554700546Z I0504 16:29:22.554146       1 shared_informer.go:262] Caches are synced for client-ca::kube-system::extension-apiserver-authentication::client-ca-file
2023-05-04T16:29:22.554700546Z I0504 16:29:22.554537       1 tlsconfig.go:178] "Loaded client CA" index=0 certName="client-ca::kube-system::extension-apiserver-authentication::client-ca-file" certDetail="\"admin-kubeconfig-signer\" [] issuer=\"<self>\" (2023-05-02 12:12:54 +0000 UTC to 2033-04-29 12:12:54 +0000 UTC (now=2023-05-04 16:29:22.554513525 +0000 UTC))"
2023-05-04T16:29:22.554700546Z I0504 16:29:22.554557       1 tlsconfig.go:178] "Loaded client CA" index=1 certName="client-ca::kube-system::extension-apiserver-authentication::client-ca-file" certDetail="\"kube-control-plane-signer\" [] issuer=\"<self>\" (2023-05-02 12:12:57 +0000 UTC to 2024-05-01 12:12:57 +0000 UTC (now=2023-05-04 16:29:22.554546747 +0000 UTC))"
2023-05-04T16:29:22.554700546Z I0504 16:29:22.554571       1 tlsconfig.go:178] "Loaded client CA" index=2 certName="client-ca::kube-system::extension-apiserver-authentication::client-ca-file" certDetail="\"kube-apiserver-to-kubelet-signer\" [] issuer=\"<self>\" (2023-05-02 12:12:57 +0000 UTC to 2024-05-01 12:12:57 +0000 UTC (now=2023-05-04 16:29:22.554562216 +0000 UTC))"
2023-05-04T16:29:22.554700546Z I0504 16:29:22.554586       1 tlsconfig.go:178] "Loaded client CA" index=3 certName="client-ca::kube-system::extension-apiserver-authentication::client-ca-file" certDetail="\"kubelet-bootstrap-kubeconfig-signer\" [] issuer=\"<self>\" (2023-05-02 12:12:55 +0000 UTC to 2033-04-29 12:12:55 +0000 UTC (now=2023-05-04 16:29:22.554576182 +0000 UTC))"
2023-05-04T16:29:22.554700546Z I0504 16:29:22.554600       1 tlsconfig.go:178] "Loaded client CA" index=4 certName="client-ca::kube-system::extension-apiserver-authentication::client-ca-file" certDetail="\"openshift-kube-apiserver-operator_node-system-admin-signer@1683031055\" [] issuer=\"<self>\" (2023-05-02 12:37:35 +0000 UTC to 2024-05-01 12:37:36 +0000 UTC (now=2023-05-04 16:29:22.55459095 +0000 UTC))"
2023-05-04T16:29:22.554700546Z I0504 16:29:22.554615       1 tlsconfig.go:178] "Loaded client CA" index=5 certName="client-ca::kube-system::extension-apiserver-authentication::client-ca-file" certDetail="\"openshift-kube-controller-manager-operator_csr-signer-signer@1683098709\" [] issuer=\"<self>\" (2023-05-03 07:25:09 +0000 UTC to 2023-07-02 07:25:10 +0000 UTC (now=2023-05-04 16:29:22.554606199 +0000 UTC))"
2023-05-04T16:29:22.554700546Z I0504 16:29:22.554640       1 tlsconfig.go:178] "Loaded client CA" index=6 certName="client-ca::kube-system::extension-apiserver-authentication::client-ca-file" certDetail="\"kube-csr-signer_@1683098906\" [] issuer=\"openshift-kube-controller-manager-operator_csr-signer-signer@1683098709\" (2023-05-03 07:28:25 +0000 UTC to 2023-06-02 07:28:26 +0000 UTC (now=2023-05-04 16:29:22.554620125 +0000 UTC))"
2023-05-04T16:29:22.554770728Z I0504 16:29:22.554756       1 tlsconfig.go:200] "Loaded serving cert" certName="serving-cert::/etc/kubernetes/static-pod-resources/secrets/serving-cert/tls.crt::/etc/kubernetes/static-pod-resources/secrets/serving-cert/tls.key" certDetail="\"scheduler.openshift-kube-scheduler.svc\" [serving] validServingFor=[scheduler.openshift-kube-scheduler.svc,scheduler.openshift-kube-scheduler.svc.cluster.local] issuer=\"openshift-service-serving-signer@1683030520\" (2023-05-02 12:30:02 +0000 UTC to 2025-05-01 12:30:03 +0000 UTC (now=2023-05-04 16:29:22.554736153 +0000 UTC))"
2023-05-04T16:29:22.554929476Z I0504 16:29:22.554834       1 named_certificates.go:53] "Loaded SNI cert" index=0 certName="self-signed loopback" certDetail="\"apiserver-loopback-client@1683217749\" [serving] validServingFor=[apiserver-loopback-client] issuer=\"apiserver-loopback-client-ca@1683217749\" (2023-05-04 15:29:08 +0000 UTC to 2024-05-03 15:29:08 +0000 UTC (now=2023-05-04 16:29:22.554822455 +0000 UTC))"
2023-05-04T16:29:22.578024153Z I0504 16:29:22.577096       1 leaderelection.go:248] attempting to acquire leader lease openshift-kube-scheduler/kube-scheduler...
2023-05-04T16:32:00.666586850Z I0504 16:32:00.666541       1 leaderelection.go:258] successfully acquired lease openshift-kube-scheduler/kube-scheduler
2023-05-04T16:32:00.676449766Z I0504 16:32:00.676422       1 schedule_one.go:266] "Successfully bound pod to node" pod="openshift-operator-lifecycle-manager/collect-profiles-28053630-ftcdh" node="node" evaluatedNodes=1 feasibleNodes=1
2023-05-04T16:33:10.769714770Z I0504 16:33:10.769633       1 schedule_one.go:266] "Successfully bound pod to node" pod="openshift-marketplace/redhat-marketplace-56wl9" node="node" evaluatedNodes=1 feasibleNodes=1
2023-05-04T16:33:10.806515310Z I0504 16:33:10.805397       1 schedule_one.go:266] "Successfully bound pod to node" pod="openshift-marketplace/redhat-operators-l9zms" node="node" evaluatedNodes=1 feasibleNodes=1
2023-05-04T16:33:12.517792967Z I0504 16:33:12.517758       1 schedule_one.go:266] "Successfully bound pod to node" pod="openshift-marketplace/certified-operators-xknh4" node="node" evaluatedNodes=1 feasibleNodes=1
2023-05-04T16:33:33.916611918Z I0504 16:33:33.916185       1 schedule_one.go:266] "Successfully bound pod to node" pod="openshift-marketplace/community-operators-jxr67" node="node" evaluatedNodes=1 feasibleNodes=1
2023-05-04T16:36:00.270305968Z I0504 16:36:00.270266       1 schedule_one.go:266] "Successfully bound pod to node" pod="openshift-multus/multus-admission-controller-65b957fdcb-cc6cn" node="node" evaluatedNodes=1 feasibleNodes=1
2023-05-04T16:36:15.736365930Z I0504 16:36:15.736332       1 schedule_one.go:266] "Successfully bound pod to node" pod="openshift-multus/cni-sysctl-allowlist-ds-cvjkq" node="node" evaluatedNodes=1 feasibleNodes=1
2023-05-04T16:43:27.710834151Z I0504 16:43:27.710040       1 schedule_one.go:266] "Successfully bound pod to node" pod="openshift-marketplace/certified-operators-qdqdv" node="node" evaluatedNodes=1 feasibleNodes=1
2023-05-04T16:43:34.510497497Z I0504 16:43:34.510466       1 schedule_one.go:266] "Successfully bound pod to node" pod="openshift-marketplace/redhat-marketplace-pc6ft" node="node" evaluatedNodes=1 feasibleNodes=1
2023-05-04T16:43:52.922929686Z I0504 16:43:52.921996       1 schedule_one.go:266] "Successfully bound pod to node" pod="openshift-marketplace/community-operators-78xxj" node="node" evaluatedNodes=1 feasibleNodes=1
2023-05-04T16:45:00.132603176Z I0504 16:45:00.132565       1 schedule_one.go:266] "Successfully bound pod to node" pod="openshift-operator-lifecycle-manager/collect-profiles-28053645-nnz6t" node="node" evaluatedNodes=1 feasibleNodes=1
2023-05-04T16:47:47.417720816Z I0504 16:47:47.409142       1 schedule_one.go:266] "Successfully bound pod to node" pod="openshift-marketplace/redhat-operators-bc9wm" node="node" evaluatedNodes=1 feasibleNodes=1
2023-05-04T16:57:47.496414459Z I0504 16:57:47.488498       1 schedule_one.go:266] "Successfully bound pod to node" pod="openshift-marketplace/redhat-operators-4ldbv" node="node" evaluatedNodes=1 feasibleNodes=1
2023-05-04T16:59:50.739590605Z I0504 16:59:50.728273       1 schedule_one.go:266] "Successfully bound pod to node" pod="topotest/topolvm-pod-2" node="node" evaluatedNodes=1 feasibleNodes=1
2023-05-04T16:59:52.886189474Z I0504 16:59:52.883495       1 schedule_one.go:266] "Successfully bound pod to node" pod="topotest/topolvm-pod-46" node="node" evaluatedNodes=1 feasibleNodes=1
2023-05-04T16:59:53.928089466Z I0504 16:59:53.927875       1 schedule_one.go:266] "Successfully bound pod to node" pod="topotest/topolvm-pod-16" node="node" evaluatedNodes=1 feasibleNodes=1
2023-05-04T16:59:53.961782261Z I0504 16:59:53.961729       1 schedule_one.go:266] "Successfully bound pod to node" pod="topotest/topolvm-pod-94" node="node" evaluatedNodes=1 feasibleNodes=1
2023-05-04T16:59:55.006697090Z I0504 16:59:55.006654       1 schedule_one.go:266] "Successfully bound pod to node" pod="topotest/topolvm-pod-30" node="node" evaluatedNodes=1 feasibleNodes=1
2023-05-04T16:59:55.048622982Z I0504 16:59:55.047645       1 schedule_one.go:266] "Successfully bound pod to node" pod="topotest/topolvm-pod-74" node="node" evaluatedNodes=1 feasibleNodes=1
2023-05-04T16:59:56.085893178Z I0504 16:59:56.085505       1 schedule_one.go:266] "Successfully bound pod to node" pod="topotest/topolvm-pod-18" node="node" evaluatedNodes=1 feasibleNodes=1
2023-05-04T16:59:56.141005901Z I0504 16:59:56.140435       1 schedule_one.go:266] "Successfully bound pod to node" pod="topotest/topolvm-pod-83" node="node" evaluatedNodes=1 feasibleNodes=1
2023-05-04T16:59:57.180376848Z I0504 16:59:57.164259       1 schedule_one.go:266] "Successfully bound pod to node" pod="topotest/topolvm-pod-8" node="node" evaluatedNodes=1 feasibleNodes=1
2023-05-04T16:59:58.212701815Z I0504 16:59:58.212490       1 schedule_one.go:266] "Successfully bound pod to node" pod="topotest/topolvm-pod-48" node="node" evaluatedNodes=1 feasibleNodes=1
2023-05-04T16:59:58.264000994Z I0504 16:59:58.263957       1 schedule_one.go:266] "Successfully bound pod to node" pod="topotest/topolvm-pod-73" node="node" evaluatedNodes=1 feasibleNodes=1
2023-05-04T16:59:59.290990541Z I0504 16:59:59.290933       1 schedule_one.go:266] "Successfully bound pod to node" pod="topotest/topolvm-pod-89" node="node" evaluatedNodes=1 feasibleNodes=1
2023-05-04T16:59:59.367380013Z I0504 16:59:59.365912       1 schedule_one.go:266] "Successfully bound pod to node" pod="topotest/topolvm-pod-77" node="node" evaluatedNodes=1 feasibleNodes=1
2023-05-04T17:00:00.201679534Z I0504 17:00:00.200641       1 schedule_one.go:266] "Successfully bound pod to node" pod="openshift-operator-lifecycle-manager/collect-profiles-28053660-qsxnq" node="node" evaluatedNodes=1 feasibleNodes=1
2023-05-04T17:00:00.440894461Z I0504 17:00:00.434217       1 schedule_one.go:266] "Successfully bound pod to node" pod="topotest/topolvm-pod-24" node="node" evaluatedNodes=1 feasibleNodes=1
2023-05-04T17:00:00.463427447Z I0504 17:00:00.462060       1 schedule_one.go:266] "Successfully bound pod to node" pod="topotest/topolvm-pod-90" node="node" evaluatedNodes=1 feasibleNodes=1
2023-05-04T17:00:01.501099627Z I0504 17:00:01.501061       1 schedule_one.go:266] "Successfully bound pod to node" pod="topotest/topolvm-pod-47" node="node" evaluatedNodes=1 feasibleNodes=1
2023-05-04T17:00:01.524475686Z I0504 17:00:01.524434       1 schedule_one.go:266] "Successfully bound pod to node" pod="topotest/topolvm-pod-31" node="node" evaluatedNodes=1 feasibleNodes=1
2023-05-04T17:00:02.614409860Z I0504 17:00:02.614271       1 schedule_one.go:266] "Successfully bound pod to node" pod="topotest/topolvm-pod-81" node="node" evaluatedNodes=1 feasibleNodes=1
2023-05-04T17:00:03.653580973Z I0504 17:00:03.652329       1 schedule_one.go:266] "Successfully bound pod to node" pod="topotest/topolvm-pod-43" node="node" evaluatedNodes=1 feasibleNodes=1
2023-05-04T17:00:07.678802701Z I0504 17:00:07.678142       1 schedule_one.go:266] "Successfully bound pod to node" pod="topotest/topolvm-pod-23" node="node" evaluatedNodes=1 feasibleNodes=1
2023-05-04T17:00:07.724783972Z I0504 17:00:07.722244       1 schedule_one.go:266] "Successfully bound pod to node" pod="topotest/topolvm-pod-17" node="node" evaluatedNodes=1 feasibleNodes=1
2023-05-04T17:00:07.773205691Z I0504 17:00:07.772116       1 schedule_one.go:266] "Successfully bound pod to node" pod="topotest/topolvm-pod-50" node="node" evaluatedNodes=1 feasibleNodes=1
2023-05-04T17:00:07.839615830Z I0504 17:00:07.839385       1 schedule_one.go:266] "Successfully bound pod to node" pod="topotest/topolvm-pod-52" node="node" evaluatedNodes=1 feasibleNodes=1
2023-05-04T17:00:07.899585395Z I0504 17:00:07.897267       1 schedule_one.go:266] "Successfully bound pod to node" pod="topotest/topolvm-pod-42" node="node" evaluatedNodes=1 feasibleNodes=1
2023-05-04T17:00:09.578368935Z I0504 17:00:09.576090       1 schedule_one.go:266] "Successfully bound pod to node" pod="topotest/topolvm-pod-91" node="node" evaluatedNodes=1 feasibleNodes=1
2023-05-04T17:00:09.594144312Z I0504 17:00:09.593528       1 schedule_one.go:266] "Successfully bound pod to node" pod="topotest/topolvm-pod-93" node="node" evaluatedNodes=1 feasibleNodes=1
2023-05-04T17:00:10.974156514Z I0504 17:00:10.972371       1 schedule_one.go:266] "Successfully bound pod to node" pod="topotest/topolvm-pod-34" node="node" evaluatedNodes=1 feasibleNodes=1
2023-05-04T17:00:11.037829358Z I0504 17:00:11.037452       1 schedule_one.go:266] "Successfully bound pod to node" pod="topotest/topolvm-pod-66" node="node" evaluatedNodes=1 feasibleNodes=1
2023-05-04T17:00:12.302025434Z I0504 17:00:12.301580       1 schedule_one.go:266] "Successfully bound pod to node" pod="topotest/topolvm-pod-56" node="node" evaluatedNodes=1 feasibleNodes=1
2023-05-04T17:00:28.388347570Z I0504 17:00:28.387021       1 schedule_one.go:266] "Successfully bound pod to node" pod="topotest/topolvm-pod-28" node="node" evaluatedNodes=1 feasibleNodes=1
2023-05-04T17:00:28.593737895Z I0504 17:00:28.593352       1 schedule_one.go:266] "Successfully bound pod to node" pod="topotest/topolvm-pod-11" node="node" evaluatedNodes=1 feasibleNodes=1
2023-05-04T17:00:42.405438214Z I0504 17:00:42.405399       1 schedule_one.go:266] "Successfully bound pod to node" pod="topotest/topolvm-pod-57" node="node" evaluatedNodes=1 feasibleNodes=1
2023-05-04T17:00:51.115425142Z I0504 17:00:51.115382       1 schedule_one.go:266] "Successfully bound pod to node" pod="topotest/topolvm-pod-78" node="node" evaluatedNodes=1 feasibleNodes=1
2023-05-04T17:01:00.441913064Z I0504 17:01:00.441367       1 schedule_one.go:266] "Successfully bound pod to node" pod="topotest/topolvm-pod-33" node="node" evaluatedNodes=1 feasibleNodes=1
2023-05-04T17:01:15.144601774Z I0504 17:01:15.144558       1 schedule_one.go:266] "Successfully bound pod to node" pod="topotest/topolvm-pod-96" node="node" evaluatedNodes=1 feasibleNodes=1
2023-05-04T17:01:15.216543471Z I0504 17:01:15.216505       1 schedule_one.go:266] "Successfully bound pod to node" pod="topotest/topolvm-pod-60" node="node" evaluatedNodes=1 feasibleNodes=1
2023-05-04T17:01:16.253004609Z I0504 17:01:16.251102       1 schedule_one.go:266] "Successfully bound pod to node" pod="topotest/topolvm-pod-7" node="node" evaluatedNodes=1 feasibleNodes=1
2023-05-04T17:01:16.296817692Z I0504 17:01:16.296772       1 schedule_one.go:266] "Successfully bound pod to node" pod="topotest/topolvm-pod-72" node="node" evaluatedNodes=1 feasibleNodes=1
2023-05-04T17:01:16.327892455Z I0504 17:01:16.327274       1 schedule_one.go:266] "Successfully bound pod to node" pod="topotest/topolvm-pod-76" node="node" evaluatedNodes=1 feasibleNodes=1
2023-05-04T17:01:16.375223317Z I0504 17:01:16.374815       1 schedule_one.go:266] "Successfully bound pod to node" pod="topotest/topolvm-pod-38" node="node" evaluatedNodes=1 feasibleNodes=1
2023-05-04T17:01:16.427855807Z I0504 17:01:16.426536       1 schedule_one.go:266] "Successfully bound pod to node" pod="topotest/topolvm-pod-53" node="node" evaluatedNodes=1 feasibleNodes=1
2023-05-04T17:01:16.452392503Z I0504 17:01:16.452354       1 schedule_one.go:266] "Successfully bound pod to node" pod="topotest/topolvm-pod-41" node="node" evaluatedNodes=1 feasibleNodes=1
2023-05-04T17:01:17.506953299Z I0504 17:01:17.506764       1 schedule_one.go:266] "Successfully bound pod to node" pod="topotest/topolvm-pod-26" node="node" evaluatedNodes=1 feasibleNodes=1
2023-05-04T17:01:17.541190576Z I0504 17:01:17.541074       1 schedule_one.go:266] "Successfully bound pod to node" pod="topotest/topolvm-pod-12" node="node" evaluatedNodes=1 feasibleNodes=1
2023-05-04T17:01:17.584626561Z I0504 17:01:17.583753       1 schedule_one.go:266] "Successfully bound pod to node" pod="topotest/topolvm-pod-67" node="node" evaluatedNodes=1 feasibleNodes=1
2023-05-04T17:01:17.649642965Z I0504 17:01:17.649604       1 schedule_one.go:266] "Successfully bound pod to node" pod="topotest/topolvm-pod-70" node="node" evaluatedNodes=1 feasibleNodes=1
2023-05-04T17:01:17.699885761Z I0504 17:01:17.699849       1 schedule_one.go:266] "Successfully bound pod to node" pod="topotest/topolvm-pod-88" node="node" evaluatedNodes=1 feasibleNodes=1
2023-05-04T17:01:17.732371030Z I0504 17:01:17.732339       1 schedule_one.go:266] "Successfully bound pod to node" pod="topotest/topolvm-pod-59" node="node" evaluatedNodes=1 feasibleNodes=1
2023-05-04T17:01:18.782826054Z I0504 17:01:18.782349       1 schedule_one.go:266] "Successfully bound pod to node" pod="topotest/topolvm-pod-58" node="node" evaluatedNodes=1 feasibleNodes=1
2023-05-04T17:01:18.832455699Z I0504 17:01:18.832410       1 schedule_one.go:266] "Successfully bound pod to node" pod="topotest/topolvm-pod-32" node="node" evaluatedNodes=1 feasibleNodes=1
2023-05-04T17:01:18.867766409Z I0504 17:01:18.867724       1 schedule_one.go:266] "Successfully bound pod to node" pod="topotest/topolvm-pod-98" node="node" evaluatedNodes=1 feasibleNodes=1
2023-05-04T17:01:18.925103125Z I0504 17:01:18.925064       1 schedule_one.go:266] "Successfully bound pod to node" pod="topotest/topolvm-pod-45" node="node" evaluatedNodes=1 feasibleNodes=1
2023-05-04T17:01:19.007026340Z I0504 17:01:19.006985       1 schedule_one.go:266] "Successfully bound pod to node" pod="topotest/topolvm-pod-71" node="node" evaluatedNodes=1 feasibleNodes=1
2023-05-04T17:01:19.033967698Z I0504 17:01:19.032340       1 schedule_one.go:266] "Successfully bound pod to node" pod="topotest/topolvm-pod-27" node="node" evaluatedNodes=1 feasibleNodes=1
2023-05-04T17:01:20.078591771Z I0504 17:01:20.078413       1 schedule_one.go:266] "Successfully bound pod to node" pod="topotest/topolvm-pod-35" node="node" evaluatedNodes=1 feasibleNodes=1
2023-05-04T17:01:20.099148199Z I0504 17:01:20.098873       1 schedule_one.go:266] "Successfully bound pod to node" pod="topotest/topolvm-pod-40" node="node" evaluatedNodes=1 feasibleNodes=1
2023-05-04T17:01:20.134718937Z I0504 17:01:20.133127       1 schedule_one.go:266] "Successfully bound pod to node" pod="topotest/topolvm-pod-97" node="node" evaluatedNodes=1 feasibleNodes=1
2023-05-04T17:01:20.163752571Z I0504 17:01:20.163709       1 schedule_one.go:266] "Successfully bound pod to node" pod="topotest/topolvm-pod-25" node="node" evaluatedNodes=1 feasibleNodes=1
2023-05-04T17:01:20.229673402Z I0504 17:01:20.229578       1 schedule_one.go:266] "Successfully bound pod to node" pod="topotest/topolvm-pod-29" node="node" evaluatedNodes=1 feasibleNodes=1
2023-05-04T17:01:20.594318292Z I0504 17:01:20.594281       1 schedule_one.go:266] "Successfully bound pod to node" pod="topotest/topolvm-pod-69" node="node" evaluatedNodes=1 feasibleNodes=1
2023-05-04T17:01:21.291550866Z I0504 17:01:21.291518       1 schedule_one.go:266] "Successfully bound pod to node" pod="topotest/topolvm-pod-86" node="node" evaluatedNodes=1 feasibleNodes=1
2023-05-04T17:01:21.642779795Z I0504 17:01:21.642734       1 schedule_one.go:266] "Successfully bound pod to node" pod="topotest/topolvm-pod-5" node="node" evaluatedNodes=1 feasibleNodes=1
2023-05-04T17:01:21.655835440Z I0504 17:01:21.655363       1 schedule_one.go:266] "Successfully bound pod to node" pod="topotest/topolvm-pod-61" node="node" evaluatedNodes=1 feasibleNodes=1
2023-05-04T17:01:21.672658844Z I0504 17:01:21.672621       1 schedule_one.go:266] "Successfully bound pod to node" pod="topotest/topolvm-pod-80" node="node" evaluatedNodes=1 feasibleNodes=1
2023-05-04T17:01:21.699216843Z I0504 17:01:21.698815       1 schedule_one.go:266] "Successfully bound pod to node" pod="topotest/topolvm-pod-87" node="node" evaluatedNodes=1 feasibleNodes=1
2023-05-04T17:01:21.736776082Z I0504 17:01:21.736738       1 schedule_one.go:266] "Successfully bound pod to node" pod="topotest/topolvm-pod-65" node="node" evaluatedNodes=1 feasibleNodes=1
2023-05-04T17:01:21.768265863Z I0504 17:01:21.764944       1 schedule_one.go:266] "Successfully bound pod to node" pod="topotest/topolvm-pod-92" node="node" evaluatedNodes=1 feasibleNodes=1
2023-05-04T17:01:22.782286658Z I0504 17:01:22.779582       1 schedule_one.go:266] "Successfully bound pod to node" pod="topotest/topolvm-pod-9" node="node" evaluatedNodes=1 feasibleNodes=1
2023-05-04T17:01:22.848747663Z I0504 17:01:22.848706       1 schedule_one.go:266] "Successfully bound pod to node" pod="topotest/topolvm-pod-13" node="node" evaluatedNodes=1 feasibleNodes=1
2023-05-04T17:01:22.889056371Z I0504 17:01:22.889019       1 schedule_one.go:266] "Successfully bound pod to node" pod="topotest/topolvm-pod-14" node="node" evaluatedNodes=1 feasibleNodes=1
2023-05-04T17:01:22.950676493Z I0504 17:01:22.950639       1 schedule_one.go:266] "Successfully bound pod to node" pod="topotest/topolvm-pod-79" node="node" evaluatedNodes=1 feasibleNodes=1
2023-05-04T17:01:23.024172056Z I0504 17:01:23.024134       1 schedule_one.go:266] "Successfully bound pod to node" pod="topotest/topolvm-pod-1" node="node" evaluatedNodes=1 feasibleNodes=1
2023-05-04T17:01:23.058244633Z I0504 17:01:23.057911       1 schedule_one.go:266] "Successfully bound pod to node" pod="topotest/topolvm-pod-55" node="node" evaluatedNodes=1 feasibleNodes=1
2023-05-04T17:01:23.149126937Z I0504 17:01:23.149031       1 schedule_one.go:266] "Successfully bound pod to node" pod="topotest/topolvm-pod-95" node="node" evaluatedNodes=1 feasibleNodes=1
2023-05-04T17:01:24.206221788Z I0504 17:01:24.205000       1 schedule_one.go:266] "Successfully bound pod to node" pod="topotest/topolvm-pod-63" node="node" evaluatedNodes=1 feasibleNodes=1
2023-05-04T17:01:24.257316212Z I0504 17:01:24.257279       1 schedule_one.go:266] "Successfully bound pod to node" pod="topotest/topolvm-pod-3" node="node" evaluatedNodes=1 feasibleNodes=1
2023-05-04T17:01:24.282565876Z I0504 17:01:24.282525       1 schedule_one.go:266] "Successfully bound pod to node" pod="topotest/topolvm-pod-10" node="node" evaluatedNodes=1 feasibleNodes=1
2023-05-04T17:01:24.336985308Z I0504 17:01:24.336840       1 schedule_one.go:266] "Successfully bound pod to node" pod="topotest/topolvm-pod-85" node="node" evaluatedNodes=1 feasibleNodes=1
2023-05-04T17:01:24.345570816Z I0504 17:01:24.343507       1 schedule_one.go:266] "Successfully bound pod to node" pod="topotest/topolvm-pod-99" node="node" evaluatedNodes=1 feasibleNodes=1
2023-05-04T17:01:25.646139034Z I0504 17:01:25.644359       1 schedule_one.go:266] "Successfully bound pod to node" pod="topotest/topolvm-pod-21" node="node" evaluatedNodes=1 feasibleNodes=1
2023-05-04T17:01:25.854301661Z I0504 17:01:25.852713       1 schedule_one.go:266] "Successfully bound pod to node" pod="topotest/topolvm-pod-6" node="node" evaluatedNodes=1 feasibleNodes=1
2023-05-04T17:01:25.854301661Z I0504 17:01:25.852810       1 schedule_one.go:266] "Successfully bound pod to node" pod="topotest/topolvm-pod-19" node="node" evaluatedNodes=1 feasibleNodes=1
2023-05-04T17:01:25.854301661Z I0504 17:01:25.852900       1 schedule_one.go:266] "Successfully bound pod to node" pod="topotest/topolvm-pod-68" node="node" evaluatedNodes=1 feasibleNodes=1
2023-05-04T17:01:26.577858375Z I0504 17:01:26.577284       1 schedule_one.go:266] "Successfully bound pod to node" pod="topotest/topolvm-pod-64" node="node" evaluatedNodes=1 feasibleNodes=1
2023-05-04T17:01:26.625227579Z I0504 17:01:26.624462       1 schedule_one.go:266] "Successfully bound pod to node" pod="topotest/topolvm-pod-75" node="node" evaluatedNodes=1 feasibleNodes=1
2023-05-04T17:01:26.649906041Z I0504 17:01:26.649869       1 schedule_one.go:266] "Successfully bound pod to node" pod="topotest/topolvm-pod-51" node="node" evaluatedNodes=1 feasibleNodes=1
2023-05-04T17:01:26.730553733Z I0504 17:01:26.730515       1 schedule_one.go:266] "Successfully bound pod to node" pod="topotest/topolvm-pod-4" node="node" evaluatedNodes=1 feasibleNodes=1
2023-05-04T17:01:26.797768081Z I0504 17:01:26.797717       1 schedule_one.go:266] "Successfully bound pod to node" pod="topotest/topolvm-pod-82" node="node" evaluatedNodes=1 feasibleNodes=1
2023-05-04T17:01:26.846870077Z I0504 17:01:26.846828       1 schedule_one.go:266] "Successfully bound pod to node" pod="topotest/topolvm-pod-44" node="node" evaluatedNodes=1 feasibleNodes=1
2023-05-04T17:01:26.876528463Z I0504 17:01:26.876487       1 schedule_one.go:266] "Successfully bound pod to node" pod="topotest/topolvm-pod-20" node="node" evaluatedNodes=1 feasibleNodes=1
2023-05-04T17:01:26.932824225Z I0504 17:01:26.932785       1 schedule_one.go:266] "Successfully bound pod to node" pod="topotest/topolvm-pod-62" node="node" evaluatedNodes=1 feasibleNodes=1
2023-05-04T17:01:26.971712748Z I0504 17:01:26.971674       1 schedule_one.go:266] "Successfully bound pod to node" pod="topotest/topolvm-pod-100" node="node" evaluatedNodes=1 feasibleNodes=1
2023-05-04T17:01:28.000104947Z I0504 17:01:28.000063       1 schedule_one.go:266] "Successfully bound pod to node" pod="topotest/topolvm-pod-39" node="node" evaluatedNodes=1 feasibleNodes=1
2023-05-04T17:01:28.020820434Z I0504 17:01:28.019519       1 schedule_one.go:266] "Successfully bound pod to node" pod="topotest/topolvm-pod-84" node="node" evaluatedNodes=1 feasibleNodes=1
2023-05-04T17:01:28.138214730Z I0504 17:01:28.137499       1 schedule_one.go:266] "Successfully bound pod to node" pod="topotest/topolvm-pod-54" node="node" evaluatedNodes=1 feasibleNodes=1
2023-05-04T17:01:28.158005932Z I0504 17:01:28.156040       1 schedule_one.go:266] "Successfully bound pod to node" pod="topotest/topolvm-pod-36" node="node" evaluatedNodes=1 feasibleNodes=1
2023-05-04T17:01:28.224417384Z I0504 17:01:28.224206       1 schedule_one.go:266] "Successfully bound pod to node" pod="topotest/topolvm-pod-49" node="node" evaluatedNodes=1 feasibleNodes=1
2023-05-04T17:01:28.253319701Z I0504 17:01:28.253286       1 schedule_one.go:266] "Successfully bound pod to node" pod="topotest/topolvm-pod-15" node="node" evaluatedNodes=1 feasibleNodes=1
2023-05-04T17:01:29.279925749Z I0504 17:01:29.279650       1 schedule_one.go:266] "Successfully bound pod to node" pod="topotest/topolvm-pod-22" node="node" evaluatedNodes=1 feasibleNodes=1
2023-05-04T17:01:29.324453151Z I0504 17:01:29.322998       1 schedule_one.go:266] "Successfully bound pod to node" pod="topotest/topolvm-pod-37" node="node" evaluatedNodes=1 feasibleNodes=1
2023-05-04T17:02:25.000684098Z I0504 17:02:25.000599       1 schedule_one.go:266] "Successfully bound pod to node" pod="openshift-marketplace/community-operators-z8xzx" node="node" evaluatedNodes=1 feasibleNodes=1
2023-05-04T17:02:25.000923267Z I0504 17:02:25.000721       1 schedule_one.go:266] "Successfully bound pod to node" pod="openshift-marketplace/redhat-marketplace-x4vdl" node="node" evaluatedNodes=1 feasibleNodes=1
2023-05-04T17:02:25.084733873Z I0504 17:02:25.084369       1 schedule_one.go:266] "Successfully bound pod to node" pod="openshift-marketplace/certified-operators-w9dgj" node="node" evaluatedNodes=1 feasibleNodes=1
2023-05-04T17:08:39.424780868Z I0504 17:08:39.424738       1 schedule_one.go:266] "Successfully bound pod to node" pod="openshift-marketplace/redhat-operators-dfgnz" node="node" evaluatedNodes=1 feasibleNodes=1
2023-05-04T17:10:42.303072843Z I0504 17:10:42.303020       1 schedule_one.go:266] "Successfully bound pod to node" pod="topotest/topolvm-pod-1" node="node" evaluatedNodes=1 feasibleNodes=1
2023-05-04T17:10:43.444177457Z I0504 17:10:43.444129       1 schedule_one.go:266] "Successfully bound pod to node" pod="topotest/topolvm-pod-33" node="node" evaluatedNodes=1 feasibleNodes=1
2023-05-04T17:10:44.490000093Z I0504 17:10:44.485023       1 schedule_one.go:266] "Successfully bound pod to node" pod="topotest/topolvm-pod-14" node="node" evaluatedNodes=1 feasibleNodes=1
2023-05-04T17:10:44.542474029Z I0504 17:10:44.542400       1 schedule_one.go:266] "Successfully bound pod to node" pod="topotest/topolvm-pod-59" node="node" evaluatedNodes=1 feasibleNodes=1
2023-05-04T17:10:45.601312173Z I0504 17:10:45.600189       1 schedule_one.go:266] "Successfully bound pod to node" pod="topotest/topolvm-pod-27" node="node" evaluatedNodes=1 feasibleNodes=1
2023-05-04T17:10:46.642876680Z I0504 17:10:46.642836       1 schedule_one.go:266] "Successfully bound pod to node" pod="topotest/topolvm-pod-75" node="node" evaluatedNodes=1 feasibleNodes=1
2023-05-04T17:10:46.685004666Z I0504 17:10:46.682803       1 schedule_one.go:266] "Successfully bound pod to node" pod="topotest/topolvm-pod-29" node="node" evaluatedNodes=1 feasibleNodes=1
2023-05-04T17:10:47.694358612Z I0504 17:10:47.694307       1 schedule_one.go:266] "Successfully bound pod to node" pod="topotest/topolvm-pod-2" node="node" evaluatedNodes=1 feasibleNodes=1
2023-05-04T17:10:47.762408792Z I0504 17:10:47.759524       1 schedule_one.go:266] "Successfully bound pod to node" pod="topotest/topolvm-pod-39" node="node" evaluatedNodes=1 feasibleNodes=1
2023-05-04T17:10:48.794300121Z I0504 17:10:48.794258       1 schedule_one.go:266] "Successfully bound pod to node" pod="topotest/topolvm-pod-13" node="node" evaluatedNodes=1 feasibleNodes=1
2023-05-04T17:10:48.853833111Z I0504 17:10:48.853092       1 schedule_one.go:266] "Successfully bound pod to node" pod="topotest/topolvm-pod-55" node="node" evaluatedNodes=1 feasibleNodes=1
2023-05-04T17:10:49.913620936Z I0504 17:10:49.912679       1 schedule_one.go:266] "Successfully bound pod to node" pod="topotest/topolvm-pod-26" node="node" evaluatedNodes=1 feasibleNodes=1
2023-05-04T17:10:49.966614367Z I0504 17:10:49.966483       1 schedule_one.go:266] "Successfully bound pod to node" pod="topotest/topolvm-pod-4" node="node" evaluatedNodes=1 feasibleNodes=1
2023-05-04T17:10:51.009581776Z I0504 17:10:51.009242       1 schedule_one.go:266] "Successfully bound pod to node" pod="topotest/topolvm-pod-84" node="node" evaluatedNodes=1 feasibleNodes=1
2023-05-04T17:10:51.078948335Z I0504 17:10:51.078905       1 schedule_one.go:266] "Successfully bound pod to node" pod="topotest/topolvm-pod-88" node="node" evaluatedNodes=1 feasibleNodes=1
2023-05-04T17:10:52.129022236Z I0504 17:10:52.127354       1 schedule_one.go:266] "Successfully bound pod to node" pod="topotest/topolvm-pod-53" node="node" evaluatedNodes=1 feasibleNodes=1
2023-05-04T17:10:53.161025104Z I0504 17:10:53.160225       1 schedule_one.go:266] "Successfully bound pod to node" pod="topotest/topolvm-pod-43" node="node" evaluatedNodes=1 feasibleNodes=1
2023-05-04T17:10:53.220443980Z I0504 17:10:53.219790       1 schedule_one.go:266] "Successfully bound pod to node" pod="topotest/topolvm-pod-87" node="node" evaluatedNodes=1 feasibleNodes=1
2023-05-04T17:10:58.238381168Z I0504 17:10:58.238208       1 schedule_one.go:266] "Successfully bound pod to node" pod="topotest/topolvm-pod-49" node="node" evaluatedNodes=1 feasibleNodes=1
2023-05-04T17:10:58.291365082Z I0504 17:10:58.290580       1 schedule_one.go:266] "Successfully bound pod to node" pod="topotest/topolvm-pod-85" node="node" evaluatedNodes=1 feasibleNodes=1
2023-05-04T17:10:58.314044190Z I0504 17:10:58.313368       1 schedule_one.go:266] "Successfully bound pod to node" pod="topotest/topolvm-pod-6" node="node" evaluatedNodes=1 feasibleNodes=1
2023-05-04T17:10:58.320908378Z I0504 17:10:58.320850       1 schedule_one.go:266] "Successfully bound pod to node" pod="topotest/topolvm-pod-44" node="node" evaluatedNodes=1 feasibleNodes=1
2023-05-04T17:10:59.351169108Z I0504 17:10:59.350477       1 schedule_one.go:266] "Successfully bound pod to node" pod="topotest/topolvm-pod-11" node="node" evaluatedNodes=1 feasibleNodes=1
2023-05-04T17:10:59.500033683Z I0504 17:10:59.499917       1 schedule_one.go:266] "Successfully bound pod to node" pod="topotest/topolvm-pod-10" node="node" evaluatedNodes=1 feasibleNodes=1
2023-05-04T17:10:59.552134921Z I0504 17:10:59.548589       1 schedule_one.go:266] "Successfully bound pod to node" pod="topotest/topolvm-pod-36" node="node" evaluatedNodes=1 feasibleNodes=1
2023-05-04T17:10:59.696663973Z I0504 17:10:59.696621       1 schedule_one.go:266] "Successfully bound pod to node" pod="topotest/topolvm-pod-54" node="node" evaluatedNodes=1 feasibleNodes=1
2023-05-04T17:10:59.710823718Z I0504 17:10:59.710777       1 schedule_one.go:266] "Successfully bound pod to node" pod="topotest/topolvm-pod-22" node="node" evaluatedNodes=1 feasibleNodes=1
2023-05-04T17:11:00.618984675Z I0504 17:11:00.618896       1 schedule_one.go:266] "Successfully bound pod to node" pod="topotest/topolvm-pod-78" node="node" evaluatedNodes=1 feasibleNodes=1
2023-05-04T17:11:00.649548927Z I0504 17:11:00.649498       1 schedule_one.go:266] "Successfully bound pod to node" pod="topotest/topolvm-pod-82" node="node" evaluatedNodes=1 feasibleNodes=1
2023-05-04T17:11:01.723321610Z I0504 17:11:01.722551       1 schedule_one.go:266] "Successfully bound pod to node" pod="topotest/topolvm-pod-48" node="node" evaluatedNodes=1 feasibleNodes=1
2023-05-04T17:11:01.767130620Z I0504 17:11:01.766956       1 schedule_one.go:266] "Successfully bound pod to node" pod="topotest/topolvm-pod-51" node="node" evaluatedNodes=1 feasibleNodes=1
2023-05-04T17:11:02.799457876Z I0504 17:11:02.799416       1 schedule_one.go:266] "Successfully bound pod to node" pod="topotest/topolvm-pod-52" node="node" evaluatedNodes=1 feasibleNodes=1
2023-05-04T17:11:03.859082716Z I0504 17:11:03.859032       1 schedule_one.go:266] "Successfully bound pod to node" pod="topotest/topolvm-pod-74" node="node" evaluatedNodes=1 feasibleNodes=1
2023-05-04T17:11:03.873549467Z I0504 17:11:03.873504       1 schedule_one.go:266] "Successfully bound pod to node" pod="topotest/topolvm-pod-7" node="node" evaluatedNodes=1 feasibleNodes=1
2023-05-04T17:11:18.696372581Z I0504 17:11:18.695908       1 schedule_one.go:266] "Successfully bound pod to node" pod="topotest/topolvm-pod-17" node="node" evaluatedNodes=1 feasibleNodes=1
2023-05-04T17:11:32.708327389Z I0504 17:11:32.708293       1 schedule_one.go:266] "Successfully bound pod to node" pod="topotest/topolvm-pod-16" node="node" evaluatedNodes=1 feasibleNodes=1
2023-05-04T17:11:32.811279038Z I0504 17:11:32.809277       1 schedule_one.go:266] "Successfully bound pod to node" pod="topotest/topolvm-pod-21" node="node" evaluatedNodes=1 feasibleNodes=1
2023-05-04T17:11:33.351403078Z I0504 17:11:33.348326       1 schedule_one.go:266] "Successfully bound pod to node" pod="topotest/topolvm-pod-63" node="node" evaluatedNodes=1 feasibleNodes=1
2023-05-04T17:11:48.022450203Z I0504 17:11:48.019910       1 schedule_one.go:266] "Successfully bound pod to node" pod="topotest/topolvm-pod-41" node="node" evaluatedNodes=1 feasibleNodes=1
2023-05-04T17:11:48.022869250Z I0504 17:11:48.022847       1 schedule_one.go:266] "Successfully bound pod to node" pod="topotest/topolvm-pod-24" node="node" evaluatedNodes=1 feasibleNodes=1
2023-05-04T17:11:49.068440554Z I0504 17:11:49.062843       1 schedule_one.go:266] "Successfully bound pod to node" pod="topotest/topolvm-pod-68" node="node" evaluatedNodes=1 feasibleNodes=1
2023-05-04T17:11:49.124671669Z I0504 17:11:49.124440       1 schedule_one.go:266] "Successfully bound pod to node" pod="topotest/topolvm-pod-60" node="node" evaluatedNodes=1 feasibleNodes=1
2023-05-04T17:11:49.156725546Z I0504 17:11:49.154458       1 schedule_one.go:266] "Successfully bound pod to node" pod="topotest/topolvm-pod-5" node="node" evaluatedNodes=1 feasibleNodes=1
2023-05-04T17:11:49.253823542Z I0504 17:11:49.251554       1 schedule_one.go:266] "Successfully bound pod to node" pod="topotest/topolvm-pod-93" node="node" evaluatedNodes=1 feasibleNodes=1
2023-05-04T17:11:49.340426087Z I0504 17:11:49.340382       1 schedule_one.go:266] "Successfully bound pod to node" pod="topotest/topolvm-pod-66" node="node" evaluatedNodes=1 feasibleNodes=1
2023-05-04T17:11:50.311951854Z I0504 17:11:50.311912       1 schedule_one.go:266] "Successfully bound pod to node" pod="topotest/topolvm-pod-34" node="node" evaluatedNodes=1 feasibleNodes=1
2023-05-04T17:11:50.330068573Z I0504 17:11:50.318142       1 schedule_one.go:266] "Successfully bound pod to node" pod="topotest/topolvm-pod-56" node="node" evaluatedNodes=1 feasibleNodes=1
2023-05-04T17:11:50.345984142Z I0504 17:11:50.345933       1 schedule_one.go:266] "Successfully bound pod to node" pod="topotest/topolvm-pod-45" node="node" evaluatedNodes=1 feasibleNodes=1
2023-05-04T17:11:50.389006246Z I0504 17:11:50.387151       1 schedule_one.go:266] "Successfully bound pod to node" pod="topotest/topolvm-pod-46" node="node" evaluatedNodes=1 feasibleNodes=1
2023-05-04T17:11:50.426069441Z I0504 17:11:50.425461       1 schedule_one.go:266] "Successfully bound pod to node" pod="topotest/topolvm-pod-81" node="node" evaluatedNodes=1 feasibleNodes=1
2023-05-04T17:11:51.459788258Z I0504 17:11:51.459747       1 schedule_one.go:266] "Successfully bound pod to node" pod="topotest/topolvm-pod-58" node="node" evaluatedNodes=1 feasibleNodes=1
2023-05-04T17:11:51.535164803Z I0504 17:11:51.535132       1 schedule_one.go:266] "Successfully bound pod to node" pod="topotest/topolvm-pod-3" node="node" evaluatedNodes=1 feasibleNodes=1
2023-05-04T17:11:51.579616028Z I0504 17:11:51.578756       1 schedule_one.go:266] "Successfully bound pod to node" pod="topotest/topolvm-pod-37" node="node" evaluatedNodes=1 feasibleNodes=1
2023-05-04T17:11:51.806078976Z I0504 17:11:51.806043       1 schedule_one.go:266] "Successfully bound pod to node" pod="topotest/topolvm-pod-23" node="node" evaluatedNodes=1 feasibleNodes=1
2023-05-04T17:11:51.809826237Z I0504 17:11:51.809784       1 schedule_one.go:266] "Successfully bound pod to node" pod="topotest/topolvm-pod-8" node="node" evaluatedNodes=1 feasibleNodes=1
2023-05-04T17:11:51.842028792Z I0504 17:11:51.841986       1 schedule_one.go:266] "Successfully bound pod to node" pod="topotest/topolvm-pod-50" node="node" evaluatedNodes=1 feasibleNodes=1
2023-05-04T17:11:51.899408763Z I0504 17:11:51.898542       1 schedule_one.go:266] "Successfully bound pod to node" pod="topotest/topolvm-pod-90" node="node" evaluatedNodes=1 feasibleNodes=1
2023-05-04T17:11:51.930450921Z I0504 17:11:51.930095       1 schedule_one.go:266] "Successfully bound pod to node" pod="topotest/topolvm-pod-95" node="node" evaluatedNodes=1 feasibleNodes=1
2023-05-04T17:11:52.960526203Z I0504 17:11:52.947581       1 schedule_one.go:266] "Successfully bound pod to node" pod="topotest/topolvm-pod-32" node="node" evaluatedNodes=1 feasibleNodes=1
2023-05-04T17:11:53.017809162Z I0504 17:11:53.014553       1 schedule_one.go:266] "Successfully bound pod to node" pod="topotest/topolvm-pod-70" node="node" evaluatedNodes=1 feasibleNodes=1
2023-05-04T17:11:53.037299598Z I0504 17:11:53.037257       1 schedule_one.go:266] "Successfully bound pod to node" pod="topotest/topolvm-pod-65" node="node" evaluatedNodes=1 feasibleNodes=1
2023-05-04T17:11:53.096220650Z I0504 17:11:53.096182       1 schedule_one.go:266] "Successfully bound pod to node" pod="topotest/topolvm-pod-64" node="node" evaluatedNodes=1 feasibleNodes=1
2023-05-04T17:11:53.136075082Z I0504 17:11:53.136029       1 schedule_one.go:266] "Successfully bound pod to node" pod="topotest/topolvm-pod-72" node="node" evaluatedNodes=1 feasibleNodes=1
2023-05-04T17:11:54.206674311Z I0504 17:11:54.206326       1 schedule_one.go:266] "Successfully bound pod to node" pod="topotest/topolvm-pod-19" node="node" evaluatedNodes=1 feasibleNodes=1
2023-05-04T17:11:54.251523372Z I0504 17:11:54.250403       1 schedule_one.go:266] "Successfully bound pod to node" pod="topotest/topolvm-pod-100" node="node" evaluatedNodes=1 feasibleNodes=1
2023-05-04T17:11:54.405348705Z I0504 17:11:54.404611       1 schedule_one.go:266] "Successfully bound pod to node" pod="topotest/topolvm-pod-18" node="node" evaluatedNodes=1 feasibleNodes=1
2023-05-04T17:11:54.458668749Z I0504 17:11:54.458621       1 schedule_one.go:266] "Successfully bound pod to node" pod="topotest/topolvm-pod-69" node="node" evaluatedNodes=1 feasibleNodes=1
2023-05-04T17:11:54.523061587Z I0504 17:11:54.520981       1 schedule_one.go:266] "Successfully bound pod to node" pod="topotest/topolvm-pod-77" node="node" evaluatedNodes=1 feasibleNodes=1
2023-05-04T17:11:54.537484967Z I0504 17:11:54.537447       1 schedule_one.go:266] "Successfully bound pod to node" pod="topotest/topolvm-pod-94" node="node" evaluatedNodes=1 feasibleNodes=1
2023-05-04T17:11:54.799439111Z I0504 17:11:54.799298       1 schedule_one.go:266] "Successfully bound pod to node" pod="topotest/topolvm-pod-71" node="node" evaluatedNodes=1 feasibleNodes=1
2023-05-04T17:12:07.577798150Z I0504 17:12:07.577741       1 schedule_one.go:266] "Successfully bound pod to node" pod="topotest/topolvm-pod-73" node="node" evaluatedNodes=1 feasibleNodes=1
2023-05-04T17:12:07.588377277Z I0504 17:12:07.588333       1 schedule_one.go:266] "Successfully bound pod to node" pod="topotest/topolvm-pod-98" node="node" evaluatedNodes=1 feasibleNodes=1
2023-05-04T17:12:08.617468621Z I0504 17:12:08.616661       1 schedule_one.go:266] "Successfully bound pod to node" pod="topotest/topolvm-pod-79" node="node" evaluatedNodes=1 feasibleNodes=1
2023-05-04T17:12:08.676318199Z I0504 17:12:08.673649       1 schedule_one.go:266] "Successfully bound pod to node" pod="topotest/topolvm-pod-15" node="node" evaluatedNodes=1 feasibleNodes=1
2023-05-04T17:12:08.693301171Z I0504 17:12:08.693272       1 schedule_one.go:266] "Successfully bound pod to node" pod="topotest/topolvm-pod-97" node="node" evaluatedNodes=1 feasibleNodes=1
2023-05-04T17:12:08.766280668Z I0504 17:12:08.766250       1 schedule_one.go:266] "Successfully bound pod to node" pod="topotest/topolvm-pod-76" node="node" evaluatedNodes=1 feasibleNodes=1
2023-05-04T17:12:08.792267211Z I0504 17:12:08.792217       1 schedule_one.go:266] "Successfully bound pod to node" pod="topotest/topolvm-pod-80" node="node" evaluatedNodes=1 feasibleNodes=1
2023-05-04T17:12:08.866164420Z I0504 17:12:08.863379       1 schedule_one.go:266] "Successfully bound pod to node" pod="topotest/topolvm-pod-57" node="node" evaluatedNodes=1 feasibleNodes=1
2023-05-04T17:12:09.886906980Z I0504 17:12:09.886530       1 schedule_one.go:266] "Successfully bound pod to node" pod="topotest/topolvm-pod-61" node="node" evaluatedNodes=1 feasibleNodes=1
2023-05-04T17:12:09.943151912Z I0504 17:12:09.943108       1 schedule_one.go:266] "Successfully bound pod to node" pod="topotest/topolvm-pod-9" node="node" evaluatedNodes=1 feasibleNodes=1
2023-05-04T17:12:10.017580217Z I0504 17:12:10.016539       1 schedule_one.go:266] "Successfully bound pod to node" pod="topotest/topolvm-pod-30" node="node" evaluatedNodes=1 feasibleNodes=1
2023-05-04T17:12:10.036835853Z I0504 17:12:10.036799       1 schedule_one.go:266] "Successfully bound pod to node" pod="topotest/topolvm-pod-89" node="node" evaluatedNodes=1 feasibleNodes=1
2023-05-04T17:12:10.099206827Z I0504 17:12:10.093390       1 schedule_one.go:266] "Successfully bound pod to node" pod="topotest/topolvm-pod-31" node="node" evaluatedNodes=1 feasibleNodes=1
2023-05-04T17:12:10.102522738Z I0504 17:12:10.102419       1 schedule_one.go:266] "Successfully bound pod to node" pod="topotest/topolvm-pod-25" node="node" evaluatedNodes=1 feasibleNodes=1
2023-05-04T17:12:11.148929407Z I0504 17:12:11.148839       1 schedule_one.go:266] "Successfully bound pod to node" pod="topotest/topolvm-pod-62" node="node" evaluatedNodes=1 feasibleNodes=1
2023-05-04T17:12:11.202667485Z I0504 17:12:11.201831       1 schedule_one.go:266] "Successfully bound pod to node" pod="topotest/topolvm-pod-91" node="node" evaluatedNodes=1 feasibleNodes=1
2023-05-04T17:12:11.226306374Z I0504 17:12:11.226267       1 schedule_one.go:266] "Successfully bound pod to node" pod="topotest/topolvm-pod-47" node="node" evaluatedNodes=1 feasibleNodes=1
2023-05-04T17:12:11.285239549Z I0504 17:12:11.284244       1 schedule_one.go:266] "Successfully bound pod to node" pod="topotest/topolvm-pod-35" node="node" evaluatedNodes=1 feasibleNodes=1
2023-05-04T17:12:11.328002256Z I0504 17:12:11.327625       1 schedule_one.go:266] "Successfully bound pod to node" pod="topotest/topolvm-pod-12" node="node" evaluatedNodes=1 feasibleNodes=1
2023-05-04T17:12:11.525583549Z I0504 17:12:11.525297       1 schedule_one.go:266] "Successfully bound pod to node" pod="topotest/topolvm-pod-40" node="node" evaluatedNodes=1 feasibleNodes=1
2023-05-04T17:12:12.441113329Z I0504 17:12:12.440612       1 schedule_one.go:266] "Successfully bound pod to node" pod="topotest/topolvm-pod-83" node="node" evaluatedNodes=1 feasibleNodes=1
2023-05-04T17:12:12.490694970Z I0504 17:12:12.490644       1 schedule_one.go:266] "Successfully bound pod to node" pod="topotest/topolvm-pod-86" node="node" evaluatedNodes=1 feasibleNodes=1
2023-05-04T17:12:12.549738301Z I0504 17:12:12.549712       1 schedule_one.go:266] "Successfully bound pod to node" pod="topotest/topolvm-pod-92" node="node" evaluatedNodes=1 feasibleNodes=1
2023-05-04T17:12:12.592531556Z I0504 17:12:12.592332       1 schedule_one.go:266] "Successfully bound pod to node" pod="topotest/topolvm-pod-67" node="node" evaluatedNodes=1 feasibleNodes=1
2023-05-04T17:12:12.630623009Z I0504 17:12:12.630284       1 schedule_one.go:266] "Successfully bound pod to node" pod="topotest/topolvm-pod-96" node="node" evaluatedNodes=1 feasibleNodes=1
2023-05-04T17:12:12.821031897Z I0504 17:12:12.819142       1 schedule_one.go:266] "Successfully bound pod to node" pod="topotest/topolvm-pod-20" node="node" evaluatedNodes=1 feasibleNodes=1
2023-05-04T17:12:14.133022859Z I0504 17:12:14.128192       1 schedule_one.go:266] "Successfully bound pod to node" pod="topotest/topolvm-pod-38" node="node" evaluatedNodes=1 feasibleNodes=1
2023-05-04T17:12:14.133022859Z I0504 17:12:14.129785       1 schedule_one.go:266] "Successfully bound pod to node" pod="topotest/topolvm-pod-99" node="node" evaluatedNodes=1 feasibleNodes=1
2023-05-04T17:12:14.550099859Z I0504 17:12:14.550058       1 schedule_one.go:266] "Successfully bound pod to node" pod="topotest/topolvm-pod-42" node="node" evaluatedNodes=1 feasibleNodes=1
2023-05-04T17:12:14.929568041Z I0504 17:12:14.927997       1 schedule_one.go:266] "Successfully bound pod to node" pod="topotest/topolvm-pod-28" node="node" evaluatedNodes=1 feasibleNodes=1
2023-05-04T17:12:28.556784128Z I0504 17:12:28.556741       1 schedule_one.go:266] "Successfully bound pod to node" pod="openshift-marketplace/certified-operators-drlsn" node="node" evaluatedNodes=1 feasibleNodes=1
2023-05-04T17:12:33.262677067Z I0504 17:12:33.262615       1 schedule_one.go:266] "Successfully bound pod to node" pod="openshift-marketplace/community-operators-5jjqf" node="node" evaluatedNodes=1 feasibleNodes=1
2023-05-04T17:13:11.977037176Z I0504 17:13:11.973833       1 schedule_one.go:266] "Successfully bound pod to node" pod="openshift-marketplace/redhat-marketplace-jgdch" node="node" evaluatedNodes=1 feasibleNodes=1
2023-05-04T17:15:00.146093066Z I0504 17:15:00.142467       1 schedule_one.go:266] "Successfully bound pod to node" pod="openshift-operator-lifecycle-manager/collect-profiles-28053675-v9shn" node="node" evaluatedNodes=1 feasibleNodes=1
2023-05-04T17:18:58.508123310Z I0504 17:18:58.506873       1 schedule_one.go:266] "Successfully bound pod to node" pod="topotest/topolvm-pod-3" node="node" evaluatedNodes=1 feasibleNodes=1
2023-05-04T17:19:00.323788739Z I0504 17:19:00.323622       1 schedule_one.go:266] "Successfully bound pod to node" pod="topotest/topolvm-pod-95" node="node" evaluatedNodes=1 feasibleNodes=1
2023-05-04T17:19:01.377364918Z I0504 17:19:01.376614       1 schedule_one.go:266] "Successfully bound pod to node" pod="topotest/topolvm-pod-23" node="node" evaluatedNodes=1 feasibleNodes=1
2023-05-04T17:19:01.446603397Z I0504 17:19:01.446557       1 schedule_one.go:266] "Successfully bound pod to node" pod="topotest/topolvm-pod-11" node="node" evaluatedNodes=1 feasibleNodes=1
2023-05-04T17:19:02.490384700Z I0504 17:19:02.490248       1 schedule_one.go:266] "Successfully bound pod to node" pod="topotest/topolvm-pod-100" node="node" evaluatedNodes=1 feasibleNodes=1
2023-05-04T17:19:03.529078469Z I0504 17:19:03.529039       1 schedule_one.go:266] "Successfully bound pod to node" pod="topotest/topolvm-pod-68" node="node" evaluatedNodes=1 feasibleNodes=1
2023-05-04T17:19:03.575290057Z I0504 17:19:03.572163       1 schedule_one.go:266] "Successfully bound pod to node" pod="topotest/topolvm-pod-87" node="node" evaluatedNodes=1 feasibleNodes=1
2023-05-04T17:19:04.615807987Z I0504 17:19:04.611239       1 schedule_one.go:266] "Successfully bound pod to node" pod="topotest/topolvm-pod-46" node="node" evaluatedNodes=1 feasibleNodes=1
2023-05-04T17:19:04.652221092Z I0504 17:19:04.650786       1 schedule_one.go:266] "Successfully bound pod to node" pod="topotest/topolvm-pod-26" node="node" evaluatedNodes=1 feasibleNodes=1
2023-05-04T17:19:05.745130695Z I0504 17:19:05.744998       1 schedule_one.go:266] "Successfully bound pod to node" pod="topotest/topolvm-pod-7" node="node" evaluatedNodes=1 feasibleNodes=1
2023-05-04T17:19:05.745209603Z I0504 17:19:05.745176       1 schedule_one.go:266] "Successfully bound pod to node" pod="topotest/topolvm-pod-44" node="node" evaluatedNodes=1 feasibleNodes=1
2023-05-04T17:19:06.784075064Z I0504 17:19:06.783443       1 schedule_one.go:266] "Successfully bound pod to node" pod="topotest/topolvm-pod-14" node="node" evaluatedNodes=1 feasibleNodes=1
2023-05-04T17:19:07.831854858Z I0504 17:19:07.830131       1 schedule_one.go:266] "Successfully bound pod to node" pod="topotest/topolvm-pod-85" node="node" evaluatedNodes=1 feasibleNodes=1
2023-05-04T17:19:07.933828892Z I0504 17:19:07.933790       1 schedule_one.go:266] "Successfully bound pod to node" pod="topotest/topolvm-pod-12" node="node" evaluatedNodes=1 feasibleNodes=1
2023-05-04T17:19:08.923272372Z I0504 17:19:08.921745       1 schedule_one.go:266] "Successfully bound pod to node" pod="topotest/topolvm-pod-10" node="node" evaluatedNodes=1 feasibleNodes=1
2023-05-04T17:19:09.951131013Z I0504 17:19:09.950747       1 schedule_one.go:266] "Successfully bound pod to node" pod="topotest/topolvm-pod-47" node="node" evaluatedNodes=1 feasibleNodes=1
2023-05-04T17:19:09.994103554Z I0504 17:19:09.989936       1 schedule_one.go:266] "Successfully bound pod to node" pod="topotest/topolvm-pod-50" node="node" evaluatedNodes=1 feasibleNodes=1
2023-05-04T17:19:10.045699593Z I0504 17:19:10.045237       1 schedule_one.go:266] "Successfully bound pod to node" pod="topotest/topolvm-pod-99" node="node" evaluatedNodes=1 feasibleNodes=1
2023-05-04T17:19:15.099375580Z I0504 17:19:15.098543       1 schedule_one.go:266] "Successfully bound pod to node" pod="topotest/topolvm-pod-2" node="node" evaluatedNodes=1 feasibleNodes=1
2023-05-04T17:19:15.140456031Z I0504 17:19:15.140417       1 schedule_one.go:266] "Successfully bound pod to node" pod="topotest/topolvm-pod-39" node="node" evaluatedNodes=1 feasibleNodes=1
2023-05-04T17:19:15.179274489Z I0504 17:19:15.179238       1 schedule_one.go:266] "Successfully bound pod to node" pod="topotest/topolvm-pod-25" node="node" evaluatedNodes=1 feasibleNodes=1
2023-05-04T17:19:15.237196616Z I0504 17:19:15.237150       1 schedule_one.go:266] "Successfully bound pod to node" pod="topotest/topolvm-pod-56" node="node" evaluatedNodes=1 feasibleNodes=1
2023-05-04T17:19:15.291640168Z I0504 17:19:15.291483       1 schedule_one.go:266] "Successfully bound pod to node" pod="topotest/topolvm-pod-48" node="node" evaluatedNodes=1 feasibleNodes=1
2023-05-04T17:19:16.736588553Z I0504 17:19:16.736516       1 schedule_one.go:266] "Successfully bound pod to node" pod="topotest/topolvm-pod-61" node="node" evaluatedNodes=1 feasibleNodes=1
2023-05-04T17:19:16.736736110Z I0504 17:19:16.736694       1 schedule_one.go:266] "Successfully bound pod to node" pod="topotest/topolvm-pod-18" node="node" evaluatedNodes=1 feasibleNodes=1
2023-05-04T17:19:16.736736110Z I0504 17:19:16.736727       1 schedule_one.go:266] "Successfully bound pod to node" pod="topotest/topolvm-pod-49" node="node" evaluatedNodes=1 feasibleNodes=1
2023-05-04T17:19:20.529978360Z I0504 17:19:20.529486       1 schedule_one.go:266] "Successfully bound pod to node" pod="topotest/topolvm-pod-29" node="node" evaluatedNodes=1 feasibleNodes=1
2023-05-04T17:19:20.545945596Z I0504 17:19:20.544627       1 schedule_one.go:266] "Successfully bound pod to node" pod="topotest/topolvm-pod-76" node="node" evaluatedNodes=1 feasibleNodes=1
2023-05-04T17:19:21.608583887Z I0504 17:19:21.607195       1 schedule_one.go:266] "Successfully bound pod to node" pod="topotest/topolvm-pod-96" node="node" evaluatedNodes=1 feasibleNodes=1
2023-05-04T17:19:22.697556604Z I0504 17:19:22.697510       1 schedule_one.go:266] "Successfully bound pod to node" pod="topotest/topolvm-pod-64" node="node" evaluatedNodes=1 feasibleNodes=1
2023-05-04T17:19:35.020841679Z I0504 17:19:35.016767       1 schedule_one.go:266] "Successfully bound pod to node" pod="topotest/topolvm-pod-59" node="node" evaluatedNodes=1 feasibleNodes=1
2023-05-04T17:19:49.037468282Z I0504 17:19:49.037321       1 schedule_one.go:266] "Successfully bound pod to node" pod="topotest/topolvm-pod-78" node="node" evaluatedNodes=1 feasibleNodes=1
2023-05-04T17:20:02.873972925Z I0504 17:20:02.873917       1 schedule_one.go:266] "Successfully bound pod to node" pod="openshift-marketplace/redhat-operators-rtj9h" node="node" evaluatedNodes=1 feasibleNodes=1
2023-05-04T17:20:07.059434189Z I0504 17:20:07.058525       1 schedule_one.go:266] "Successfully bound pod to node" pod="topotest/topolvm-pod-24" node="node" evaluatedNodes=1 feasibleNodes=1
2023-05-04T17:20:08.963099164Z I0504 17:20:08.961755       1 schedule_one.go:266] "Successfully bound pod to node" pod="topotest/topolvm-pod-75" node="node" evaluatedNodes=1 feasibleNodes=1
2023-05-04T17:20:09.093306768Z I0504 17:20:09.092513       1 schedule_one.go:266] "Successfully bound pod to node" pod="topotest/topolvm-pod-55" node="node" evaluatedNodes=1 feasibleNodes=1
2023-05-04T17:20:09.164153443Z I0504 17:20:09.163911       1 schedule_one.go:266] "Successfully bound pod to node" pod="topotest/topolvm-pod-94" node="node" evaluatedNodes=1 feasibleNodes=1
2023-05-04T17:20:09.682426408Z I0504 17:20:09.682386       1 schedule_one.go:266] "Successfully bound pod to node" pod="topotest/topolvm-pod-37" node="node" evaluatedNodes=1 feasibleNodes=1
2023-05-04T17:20:09.728538760Z I0504 17:20:09.728497       1 schedule_one.go:266] "Successfully bound pod to node" pod="topotest/topolvm-pod-60" node="node" evaluatedNodes=1 feasibleNodes=1
2023-05-04T17:20:10.738819001Z I0504 17:20:10.738777       1 schedule_one.go:266] "Successfully bound pod to node" pod="topotest/topolvm-pod-82" node="node" evaluatedNodes=1 feasibleNodes=1
2023-05-04T17:20:10.778650980Z I0504 17:20:10.778609       1 schedule_one.go:266] "Successfully bound pod to node" pod="topotest/topolvm-pod-13" node="node" evaluatedNodes=1 feasibleNodes=1
2023-05-04T17:20:10.845427219Z I0504 17:20:10.843258       1 schedule_one.go:266] "Successfully bound pod to node" pod="topotest/topolvm-pod-8" node="node" evaluatedNodes=1 feasibleNodes=1
2023-05-04T17:20:10.869505954Z I0504 17:20:10.867945       1 schedule_one.go:266] "Successfully bound pod to node" pod="topotest/topolvm-pod-57" node="node" evaluatedNodes=1 feasibleNodes=1
2023-05-04T17:20:11.074426997Z I0504 17:20:11.074390       1 schedule_one.go:266] "Successfully bound pod to node" pod="topotest/topolvm-pod-93" node="node" evaluatedNodes=1 feasibleNodes=1
2023-05-04T17:20:11.095168350Z I0504 17:20:11.094463       1 schedule_one.go:266] "Successfully bound pod to node" pod="topotest/topolvm-pod-34" node="node" evaluatedNodes=1 feasibleNodes=1
2023-05-04T17:20:12.123081743Z I0504 17:20:12.123016       1 schedule_one.go:266] "Successfully bound pod to node" pod="topotest/topolvm-pod-74" node="node" evaluatedNodes=1 feasibleNodes=1
2023-05-04T17:20:12.168466620Z I0504 17:20:12.167138       1 schedule_one.go:266] "Successfully bound pod to node" pod="topotest/topolvm-pod-17" node="node" evaluatedNodes=1 feasibleNodes=1
2023-05-04T17:20:12.238530187Z I0504 17:20:12.237916       1 schedule_one.go:266] "Successfully bound pod to node" pod="topotest/topolvm-pod-15" node="node" evaluatedNodes=1 feasibleNodes=1
2023-05-04T17:20:12.298103102Z I0504 17:20:12.297312       1 schedule_one.go:266] "Successfully bound pod to node" pod="topotest/topolvm-pod-97" node="node" evaluatedNodes=1 feasibleNodes=1
2023-05-04T17:20:12.325039828Z I0504 17:20:12.323283       1 schedule_one.go:266] "Successfully bound pod to node" pod="topotest/topolvm-pod-38" node="node" evaluatedNodes=1 feasibleNodes=1
2023-05-04T17:20:12.363716259Z I0504 17:20:12.360751       1 schedule_one.go:266] "Successfully bound pod to node" pod="topotest/topolvm-pod-84" node="node" evaluatedNodes=1 feasibleNodes=1
2023-05-04T17:20:13.424307399Z I0504 17:20:13.424263       1 schedule_one.go:266] "Successfully bound pod to node" pod="topotest/topolvm-pod-40" node="node" evaluatedNodes=1 feasibleNodes=1
2023-05-04T17:20:13.477273599Z I0504 17:20:13.477163       1 schedule_one.go:266] "Successfully bound pod to node" pod="topotest/topolvm-pod-52" node="node" evaluatedNodes=1 feasibleNodes=1
2023-05-04T17:20:13.543671379Z I0504 17:20:13.543620       1 schedule_one.go:266] "Successfully bound pod to node" pod="topotest/topolvm-pod-19" node="node" evaluatedNodes=1 feasibleNodes=1
2023-05-04T17:20:13.597282579Z I0504 17:20:13.597243       1 schedule_one.go:266] "Successfully bound pod to node" pod="topotest/topolvm-pod-45" node="node" evaluatedNodes=1 feasibleNodes=1
2023-05-04T17:20:13.659029533Z I0504 17:20:13.658245       1 schedule_one.go:266] "Successfully bound pod to node" pod="topotest/topolvm-pod-5" node="node" evaluatedNodes=1 feasibleNodes=1
2023-05-04T17:20:13.663263886Z I0504 17:20:13.663232       1 schedule_one.go:266] "Successfully bound pod to node" pod="topotest/topolvm-pod-6" node="node" evaluatedNodes=1 feasibleNodes=1
2023-05-04T17:20:14.691265626Z I0504 17:20:14.689623       1 schedule_one.go:266] "Successfully bound pod to node" pod="topotest/topolvm-pod-91" node="node" evaluatedNodes=1 feasibleNodes=1
2023-05-04T17:20:14.743656146Z I0504 17:20:14.741612       1 schedule_one.go:266] "Successfully bound pod to node" pod="topotest/topolvm-pod-20" node="node" evaluatedNodes=1 feasibleNodes=1
2023-05-04T17:20:14.754819579Z I0504 17:20:14.754107       1 schedule_one.go:266] "Successfully bound pod to node" pod="topotest/topolvm-pod-70" node="node" evaluatedNodes=1 feasibleNodes=1
2023-05-04T17:20:14.825579713Z I0504 17:20:14.822433       1 schedule_one.go:266] "Successfully bound pod to node" pod="topotest/topolvm-pod-71" node="node" evaluatedNodes=1 feasibleNodes=1
2023-05-04T17:20:14.842400791Z I0504 17:20:14.842359       1 schedule_one.go:266] "Successfully bound pod to node" pod="topotest/topolvm-pod-81" node="node" evaluatedNodes=1 feasibleNodes=1
2023-05-04T17:20:14.934388720Z I0504 17:20:14.932016       1 schedule_one.go:266] "Successfully bound pod to node" pod="topotest/topolvm-pod-62" node="node" evaluatedNodes=1 feasibleNodes=1
2023-05-04T17:20:14.968902983Z I0504 17:20:14.968687       1 schedule_one.go:266] "Successfully bound pod to node" pod="topotest/topolvm-pod-98" node="node" evaluatedNodes=1 feasibleNodes=1
2023-05-04T17:20:16.015587232Z I0504 17:20:16.015481       1 schedule_one.go:266] "Successfully bound pod to node" pod="topotest/topolvm-pod-83" node="node" evaluatedNodes=1 feasibleNodes=1
2023-05-04T17:20:16.054397063Z I0504 17:20:16.051921       1 schedule_one.go:266] "Successfully bound pod to node" pod="topotest/topolvm-pod-66" node="node" evaluatedNodes=1 feasibleNodes=1
2023-05-04T17:20:16.113378969Z I0504 17:20:16.111665       1 schedule_one.go:266] "Successfully bound pod to node" pod="topotest/topolvm-pod-88" node="node" evaluatedNodes=1 feasibleNodes=1
2023-05-04T17:20:16.195785533Z I0504 17:20:16.195743       1 schedule_one.go:266] "Successfully bound pod to node" pod="topotest/topolvm-pod-9" node="node" evaluatedNodes=1 feasibleNodes=1
2023-05-04T17:20:16.242167100Z I0504 17:20:16.242106       1 schedule_one.go:266] "Successfully bound pod to node" pod="topotest/topolvm-pod-42" node="node" evaluatedNodes=1 feasibleNodes=1
2023-05-04T17:20:17.729442815Z I0504 17:20:17.729330       1 schedule_one.go:266] "Successfully bound pod to node" pod="topotest/topolvm-pod-72" node="node" evaluatedNodes=1 feasibleNodes=1
2023-05-04T17:20:17.730354435Z I0504 17:20:17.729589       1 schedule_one.go:266] "Successfully bound pod to node" pod="topotest/topolvm-pod-43" node="node" evaluatedNodes=1 feasibleNodes=1
2023-05-04T17:20:18.404348468Z I0504 17:20:18.400272       1 schedule_one.go:266] "Successfully bound pod to node" pod="topotest/topolvm-pod-51" node="node" evaluatedNodes=1 feasibleNodes=1
2023-05-04T17:20:19.358501640Z I0504 17:20:19.357686       1 schedule_one.go:266] "Successfully bound pod to node" pod="topotest/topolvm-pod-89" node="node" evaluatedNodes=1 feasibleNodes=1
2023-05-04T17:20:19.416674137Z I0504 17:20:19.416339       1 schedule_one.go:266] "Successfully bound pod to node" pod="topotest/topolvm-pod-73" node="node" evaluatedNodes=1 feasibleNodes=1
2023-05-04T17:20:19.467003961Z I0504 17:20:19.465216       1 schedule_one.go:266] "Successfully bound pod to node" pod="topotest/topolvm-pod-80" node="node" evaluatedNodes=1 feasibleNodes=1
2023-05-04T17:20:19.478075402Z I0504 17:20:19.477829       1 schedule_one.go:266] "Successfully bound pod to node" pod="topotest/topolvm-pod-16" node="node" evaluatedNodes=1 feasibleNodes=1
2023-05-04T17:20:19.521462491Z I0504 17:20:19.520087       1 schedule_one.go:266] "Successfully bound pod to node" pod="topotest/topolvm-pod-21" node="node" evaluatedNodes=1 feasibleNodes=1
2023-05-04T17:20:19.576492483Z I0504 17:20:19.576443       1 schedule_one.go:266] "Successfully bound pod to node" pod="topotest/topolvm-pod-35" node="node" evaluatedNodes=1 feasibleNodes=1
2023-05-04T17:20:19.623059448Z I0504 17:20:19.622221       1 schedule_one.go:266] "Successfully bound pod to node" pod="topotest/topolvm-pod-54" node="node" evaluatedNodes=1 feasibleNodes=1
2023-05-04T17:20:19.684176520Z I0504 17:20:19.681949       1 schedule_one.go:266] "Successfully bound pod to node" pod="topotest/topolvm-pod-33" node="node" evaluatedNodes=1 feasibleNodes=1
2023-05-04T17:20:19.723796641Z I0504 17:20:19.722695       1 schedule_one.go:266] "Successfully bound pod to node" pod="topotest/topolvm-pod-58" node="node" evaluatedNodes=1 feasibleNodes=1
2023-05-04T17:20:19.763551836Z I0504 17:20:19.762338       1 schedule_one.go:266] "Successfully bound pod to node" pod="topotest/topolvm-pod-28" node="node" evaluatedNodes=1 feasibleNodes=1
2023-05-04T17:20:19.812724600Z I0504 17:20:19.812555       1 schedule_one.go:266] "Successfully bound pod to node" pod="topotest/topolvm-pod-31" node="node" evaluatedNodes=1 feasibleNodes=1
2023-05-04T17:20:19.845140976Z I0504 17:20:19.842760       1 schedule_one.go:266] "Successfully bound pod to node" pod="topotest/topolvm-pod-36" node="node" evaluatedNodes=1 feasibleNodes=1
2023-05-04T17:20:19.870698565Z I0504 17:20:19.870570       1 schedule_one.go:266] "Successfully bound pod to node" pod="topotest/topolvm-pod-90" node="node" evaluatedNodes=1 feasibleNodes=1
2023-05-04T17:20:20.006725626Z I0504 17:20:20.006134       1 schedule_one.go:266] "Successfully bound pod to node" pod="topotest/topolvm-pod-53" node="node" evaluatedNodes=1 feasibleNodes=1
2023-05-04T17:20:20.163002517Z I0504 17:20:20.162331       1 schedule_one.go:266] "Successfully bound pod to node" pod="topotest/topolvm-pod-41" node="node" evaluatedNodes=1 feasibleNodes=1
2023-05-04T17:20:20.222429299Z I0504 17:20:20.222391       1 schedule_one.go:266] "Successfully bound pod to node" pod="topotest/topolvm-pod-27" node="node" evaluatedNodes=1 feasibleNodes=1
2023-05-04T17:20:20.254548768Z I0504 17:20:20.254506       1 schedule_one.go:266] "Successfully bound pod to node" pod="topotest/topolvm-pod-32" node="node" evaluatedNodes=1 feasibleNodes=1
2023-05-04T17:20:21.291844524Z I0504 17:20:21.291786       1 schedule_one.go:266] "Successfully bound pod to node" pod="topotest/topolvm-pod-69" node="node" evaluatedNodes=1 feasibleNodes=1
2023-05-04T17:20:21.295820012Z I0504 17:20:21.295772       1 schedule_one.go:266] "Successfully bound pod to node" pod="topotest/topolvm-pod-79" node="node" evaluatedNodes=1 feasibleNodes=1
2023-05-04T17:20:21.325154908Z I0504 17:20:21.324176       1 schedule_one.go:266] "Successfully bound pod to node" pod="topotest/topolvm-pod-4" node="node" evaluatedNodes=1 feasibleNodes=1
2023-05-04T17:20:21.382494142Z I0504 17:20:21.380472       1 schedule_one.go:266] "Successfully bound pod to node" pod="topotest/topolvm-pod-65" node="node" evaluatedNodes=1 feasibleNodes=1
2023-05-04T17:20:21.435588723Z I0504 17:20:21.435395       1 schedule_one.go:266] "Successfully bound pod to node" pod="topotest/topolvm-pod-86" node="node" evaluatedNodes=1 feasibleNodes=1
2023-05-04T17:20:21.503367733Z I0504 17:20:21.502758       1 schedule_one.go:266] "Successfully bound pod to node" pod="topotest/topolvm-pod-22" node="node" evaluatedNodes=1 feasibleNodes=1
2023-05-04T17:20:22.579313230Z I0504 17:20:22.579090       1 schedule_one.go:266] "Successfully bound pod to node" pod="topotest/topolvm-pod-1" node="node" evaluatedNodes=1 feasibleNodes=1
2023-05-04T17:20:22.589252176Z I0504 17:20:22.589134       1 schedule_one.go:266] "Successfully bound pod to node" pod="topotest/topolvm-pod-92" node="node" evaluatedNodes=1 feasibleNodes=1
2023-05-04T17:20:22.635953473Z I0504 17:20:22.635918       1 schedule_one.go:266] "Successfully bound pod to node" pod="topotest/topolvm-pod-77" node="node" evaluatedNodes=1 feasibleNodes=1
2023-05-04T17:20:22.662238015Z I0504 17:20:22.662196       1 schedule_one.go:266] "Successfully bound pod to node" pod="topotest/topolvm-pod-30" node="node" evaluatedNodes=1 feasibleNodes=1
2023-05-04T17:20:22.745174523Z I0504 17:20:22.741046       1 schedule_one.go:266] "Successfully bound pod to node" pod="topotest/topolvm-pod-63" node="node" evaluatedNodes=1 feasibleNodes=1
2023-05-04T17:20:23.767733441Z I0504 17:20:23.767692       1 schedule_one.go:266] "Successfully bound pod to node" pod="topotest/topolvm-pod-67" node="node" evaluatedNodes=1 feasibleNodes=1
2023-05-04T17:23:46.577273315Z I0504 17:23:46.576858       1 schedule_one.go:266] "Successfully bound pod to node" pod="openshift-marketplace/community-operators-cqrtj" node="node" evaluatedNodes=1 feasibleNodes=1
2023-05-04T17:23:47.840381829Z I0504 17:23:47.838406       1 schedule_one.go:266] "Successfully bound pod to node" pod="openshift-marketplace/certified-operators-bszdl" node="node" evaluatedNodes=1 feasibleNodes=1
2023-05-04T17:30:00.177126547Z I0504 17:30:00.176534       1 schedule_one.go:266] "Successfully bound pod to node" pod="openshift-operator-lifecycle-manager/collect-profiles-28053690-8n8vm" node="node" evaluatedNodes=1 feasibleNodes=1
2023-05-04T17:31:40.156775801Z I0504 17:31:40.154874       1 schedule_one.go:266] "Successfully bound pod to node" pod="openshift-marketplace/redhat-operators-w85ll" node="node" evaluatedNodes=1 feasibleNodes=1
2023-05-04T17:31:40.162711559Z I0504 17:31:40.162668       1 schedule_one.go:266] "Successfully bound pod to node" pod="openshift-marketplace/redhat-marketplace-km57h" node="node" evaluatedNodes=1 feasibleNodes=1
2023-05-04T17:33:48.824408766Z I0504 17:33:48.824365       1 schedule_one.go:266] "Successfully bound pod to node" pod="openshift-marketplace/community-operators-nk5tf" node="node" evaluatedNodes=1 feasibleNodes=1
2023-05-04T17:35:11.624524118Z I0504 17:35:11.623155       1 schedule_one.go:266] "Successfully bound pod to node" pod="openshift-marketplace/certified-operators-drpfq" node="node" evaluatedNodes=1 feasibleNodes=1
2023-05-04T17:42:44.098440486Z I0504 17:42:44.098407       1 schedule_one.go:266] "Successfully bound pod to node" pod="openshift-marketplace/redhat-operators-gcxrt" node="node" evaluatedNodes=1 feasibleNodes=1
2023-05-04T17:43:04.515326820Z I0504 17:43:04.515213       1 schedule_one.go:266] "Successfully bound pod to node" pod="openshift-marketplace/redhat-marketplace-ff4mn" node="node" evaluatedNodes=1 feasibleNodes=1
2023-05-04T17:44:43.007513139Z I0504 17:44:43.006690       1 schedule_one.go:266] "Successfully bound pod to node" pod="openshift-marketplace/community-operators-2q2dp" node="node" evaluatedNodes=1 feasibleNodes=1
2023-05-04T17:45:00.139514361Z I0504 17:45:00.139464       1 schedule_one.go:266] "Successfully bound pod to node" pod="openshift-operator-lifecycle-manager/collect-profiles-28053705-2kjn2" node="node" evaluatedNodes=1 feasibleNodes=1
2023-05-04T17:46:14.677288538Z I0504 17:46:14.677245       1 schedule_one.go:266] "Successfully bound pod to node" pod="openshift-marketplace/certified-operators-z99xj" node="node" evaluatedNodes=1 feasibleNodes=1
2023-05-04T17:53:06.027587146Z I0504 17:53:06.027541       1 schedule_one.go:266] "Successfully bound pod to node" pod="openshift-marketplace/redhat-marketplace-v2pf2" node="node" evaluatedNodes=1 feasibleNodes=1
2023-05-04T17:53:06.057825642Z I0504 17:53:06.057592       1 schedule_one.go:266] "Successfully bound pod to node" pod="openshift-marketplace/redhat-operators-wbccq" node="node" evaluatedNodes=1 feasibleNodes=1
2023-05-04T17:55:27.049457027Z I0504 17:55:27.049352       1 schedule_one.go:266] "Successfully bound pod to node" pod="openshift-marketplace/community-operators-l2sg7" node="node" evaluatedNodes=1 feasibleNodes=1
2023-05-04T17:56:19.679501482Z I0504 17:56:19.679457       1 schedule_one.go:266] "Successfully bound pod to node" pod="openshift-marketplace/certified-operators-v4nhw" node="node" evaluatedNodes=1 feasibleNodes=1
2023-05-04T18:00:00.137832734Z I0504 18:00:00.137779       1 schedule_one.go:266] "Successfully bound pod to node" pod="openshift-operator-lifecycle-manager/collect-profiles-28053720-h9jpd" node="node" evaluatedNodes=1 feasibleNodes=1
2023-05-04T18:03:29.426057124Z I0504 18:03:29.425211       1 schedule_one.go:266] "Successfully bound pod to node" pod="openshift-marketplace/redhat-operators-xrwgt" node="node" evaluatedNodes=1 feasibleNodes=1
2023-05-04T18:03:36.370249943Z I0504 18:03:36.369883       1 schedule_one.go:266] "Successfully bound pod to node" pod="openshift-marketplace/redhat-marketplace-f9hwc" node="node" evaluatedNodes=1 feasibleNodes=1
2023-05-04T18:06:42.538824319Z I0504 18:06:42.538765       1 schedule_one.go:266] "Successfully bound pod to node" pod="openshift-marketplace/community-operators-ldq2d" node="node" evaluatedNodes=1 feasibleNodes=1
2023-05-04T18:06:53.883837129Z I0504 18:06:53.882336       1 schedule_one.go:266] "Successfully bound pod to node" pod="openshift-marketplace/certified-operators-4xrck" node="node" evaluatedNodes=1 feasibleNodes=1
2023-05-04T18:13:36.633574782Z I0504 18:13:36.633516       1 schedule_one.go:266] "Successfully bound pod to node" pod="openshift-marketplace/redhat-operators-ndvhc" node="node" evaluatedNodes=1 feasibleNodes=1
2023-05-04T18:14:36.367406939Z I0504 18:14:36.367356       1 schedule_one.go:266] "Successfully bound pod to node" pod="openshift-marketplace/redhat-marketplace-67sdf" node="node" evaluatedNodes=1 feasibleNodes=1
2023-05-04T18:15:00.136853804Z I0504 18:15:00.136059       1 schedule_one.go:266] "Successfully bound pod to node" pod="openshift-operator-lifecycle-manager/collect-profiles-28053735-l5dns" node="node" evaluatedNodes=1 feasibleNodes=1
2023-05-04T18:18:04.299832387Z I0504 18:18:04.297729       1 schedule_one.go:266] "Successfully bound pod to node" pod="openshift-marketplace/community-operators-nhqkg" node="node" evaluatedNodes=1 feasibleNodes=1
2023-05-04T18:22:33.589016142Z I0504 18:22:33.588021       1 schedule_one.go:266] "Successfully bound pod to node" pod="openshift-marketplace/certified-operators-t6fmx" node="node" evaluatedNodes=1 feasibleNodes=1
2023-05-04T18:25:04.536697179Z I0504 18:25:04.536657       1 schedule_one.go:266] "Successfully bound pod to node" pod="openshift-marketplace/redhat-marketplace-ln69j" node="node" evaluatedNodes=1 feasibleNodes=1
2023-05-04T18:25:04.560050033Z I0504 18:25:04.559049       1 schedule_one.go:266] "Successfully bound pod to node" pod="openshift-marketplace/redhat-operators-9d7l7" node="node" evaluatedNodes=1 feasibleNodes=1
2023-05-04T18:30:00.172842628Z I0504 18:30:00.172798       1 schedule_one.go:266] "Successfully bound pod to node" pod="openshift-operator-lifecycle-manager/collect-profiles-28053750-sn7bs" node="node" evaluatedNodes=1 feasibleNodes=1
2023-05-04T18:30:10.455778700Z I0504 18:30:10.455672       1 schedule_one.go:266] "Successfully bound pod to node" pod="openshift-marketplace/community-operators-pv5c6" node="node" evaluatedNodes=1 feasibleNodes=1
2023-05-04T18:32:35.798163889Z I0504 18:32:35.797992       1 schedule_one.go:266] "Successfully bound pod to node" pod="openshift-marketplace/certified-operators-m76fd" node="node" evaluatedNodes=1 feasibleNodes=1
2023-05-04T18:35:17.890826114Z I0504 18:35:17.888236       1 schedule_one.go:266] "Successfully bound pod to node" pod="openshift-marketplace/redhat-marketplace-b6qgh" node="node" evaluatedNodes=1 feasibleNodes=1
2023-05-04T18:38:11.253760047Z I0504 18:38:11.253715       1 schedule_one.go:266] "Successfully bound pod to node" pod="openshift-marketplace/redhat-operators-s822z" node="node" evaluatedNodes=1 feasibleNodes=1
2023-05-04T18:41:03.768266971Z I0504 18:41:03.768212       1 schedule_one.go:266] "Successfully bound pod to node" pod="openshift-marketplace/community-operators-c8zkr" node="node" evaluatedNodes=1 feasibleNodes=1
2023-05-04T18:43:23.752766218Z I0504 18:43:23.750542       1 schedule_one.go:266] "Successfully bound pod to node" pod="openshift-marketplace/certified-operators-kd56g" node="node" evaluatedNodes=1 feasibleNodes=1
2023-05-04T18:45:00.139176566Z I0504 18:45:00.139136       1 schedule_one.go:266] "Successfully bound pod to node" pod="openshift-operator-lifecycle-manager/collect-profiles-28053765-v8rqc" node="node" evaluatedNodes=1 feasibleNodes=1
2023-05-04T18:46:28.960103741Z I0504 18:46:28.951946       1 schedule_one.go:266] "Successfully bound pod to node" pod="openshift-must-gather-7nvg4/must-gather-7x49h" node="node" evaluatedNodes=1 feasibleNodes=1
2023-05-04T18:46:31.372531610Z I0504 18:46:31.372486       1 schedule_one.go:266] "Successfully bound pod to node" pod="openshift-marketplace/redhat-marketplace-rlcps" node="node" evaluatedNodes=1 feasibleNodes=1
